<?xml version="1.0" ?>
<!-- =================================================================================== -->
<!-- |    This document was autogenerated by xacro from le_arm.xacro                   | -->
<!-- |    EDITING THIS FILE BY HAND IS NOT RECOMMENDED                                 | -->
<!-- =================================================================================== -->
<robot name="le_arm">
  <gazebo>
    <plugin filename="libgazebo_ros_control.so" name="gazebo_ros_control">
      <robotNamespace>/</robotNamespace>
    </plugin>
  </gazebo>
  <link name="world"/>
  <joint name="world_fixed" type="fixed">
    <origin rpy="0 0 0" xyz="0 0 0"/>
    <parent link="world"/>
    <child link="root_link"/>
  </joint>
  <link name="root_link">
    <visual>
      <origin rpy="0 0 0" xyz="0 0 0.025"/>
      <geometry>
        <box size="0.5 0.15 0.05"/>
      </geometry>
    </visual>
    <collision>
      <origin rpy="0 0 0" xyz="0 0 0.025"/>
      <geometry>
        <box size="0.5 0.15 0.05"/>
      </geometry>
    </collision>
    <inertial>
      <mass value="0.01"/>
      <origin xyz="0.0 0.0 0.0"/>
      <inertia ixx="0.000001" ixy="0.000000" ixz="0.000000" iyx="0.000000" iyy="0.000001" iyz="0.000000" izx="0.000000" izy="0.000000" izz="0.000001"/>
    </inertial>
  </link>
  <joint name="arm_base_joint" type="fixed">
    <parent link="root_link"/>
    <child link="arm_base_link"/>
    <origin rpy="0 0 0" xyz="0.05 0 0.051"/>
  </joint>
  <link name="arm_base_link">
    <inertial>
      <origin rpy="0 0 0" xyz="0.034411 3.2244E-06 0.02029"/>
      <mass value="0.00001"/>
      <inertia ixx="0.001" ixy="0.0" ixz="0.0" iyy="0.001" iyz="0.0" izz="0.001"/>
    </inertial>
    <visual>
      <origin rpy="0 0 0" xyz="0 0 0"/>
      <geometry>
        <mesh filename="package://le_arm/meshes/arm/base_link.STL"/>
      </geometry>
      <material name="">
        <color rgba="0.75294 0.75294 0.75294 1"/>
      </material>
    </visual>
    <collision>
      <origin rpy="0 0 0" xyz="0 0 0"/>
      <geometry>
        <mesh filename="package://le_arm/meshes/arm/base_link.STL"/>
      </geometry>
    </collision>
  </link>
  <gazebo reference="arm_base_link">
    <implicitSpringDamper>1</implicitSpringDamper>
    <mu1>100000</mu1>
    <mu2>100000</mu2>
    <kp>100000000.0</kp>
    <kd>1.0</kd>
  </gazebo>
  <link name="shoulder_link">
    <inertial>
      <origin rpy="0 0 0" xyz="-0.0005946 -0.00090913 0.017195"/>
      <mass value="0.00001"/>
      <inertia ixx="0.001" ixy="0.0" ixz="0.0" iyy="0.001" iyz="0.0" izz="0.001"/>
    </inertial>
    <visual>
      <origin rpy="0 0 0" xyz="0 0 0"/>
      <geometry>
        <mesh filename="package://le_arm/meshes/arm/shoulder_link.STL"/>
      </geometry>
      <material name="">
        <color rgba="0.75294 0.75294 0.75294 1"/>
      </material>
    </visual>
    <collision>
      <origin rpy="0 0 0" xyz="0 0 0"/>
      <geometry>
        <mesh filename="package://le_arm/meshes/arm/shoulder_link.STL"/>
      </geometry>
    </collision>
  </link>
  <gazebo reference="shoulder_link">
    <implicitSpringDamper>1</implicitSpringDamper>
    <mu1>100000</mu1>
    <mu2>100000</mu2>
    <kp>100000000.0</kp>
    <kd>1.0</kd>
  </gazebo>
  <joint name="shoulder_pan_joint" type="revolute">
    <origin rpy="1.2297E-10 2.2825E-27 -3.4694E-17" xyz="0.0005 0 0.0535"/>
    <parent link="arm_base_link"/>
    <child link="shoulder_link"/>
    <axis xyz="0 0 1"/>
    <limit effort="1000" lower="-1.57" upper="1.57" velocity="2"/>
  </joint>
  <link name="upper_arm_link">
    <inertial>
      <origin rpy="0 0 0" xyz="2.6345E-08 -0.02405 0.05197"/>
      <mass value="0.00001"/>
      <inertia ixx="0.001" ixy="0.0" ixz="0.0" iyy="0.001" iyz="0.0" izz="0.001"/>
    </inertial>
    <visual>
      <origin rpy="0 0 0" xyz="0 0 0"/>
      <geometry>
        <mesh filename="package://le_arm/meshes/arm/upper_arm_link.STL"/>
      </geometry>
      <material name="">
        <color rgba="0.75294 0.75294 0.75294 1"/>
      </material>
    </visual>
    <collision>
      <origin rpy="0 0 0" xyz="0 0 0"/>
      <geometry>
        <mesh filename="package://le_arm/meshes/arm/upper_arm_link.STL"/>
      </geometry>
    </collision>
  </link>
  <gazebo reference="upper_arm_link">
    <implicitSpringDamper>1</implicitSpringDamper>
    <mu1>100000</mu1>
    <mu2>100000</mu2>
    <kp>100000000.0</kp>
    <kd>1.0</kd>
  </gazebo>
  <joint name="shoulder_lift_joint" type="revolute">
    <origin rpy="-5.7183E-11 0.785 0" xyz="-0.0105 0.0226 0.032"/>
    <parent link="shoulder_link"/>
    <child link="upper_arm_link"/>
    <axis xyz="0 -1 0"/>
    <limit effort="1000" lower="-1.57" upper="1.57" velocity="2"/>
  </joint>
  <link name="forearm_link">
    <inertial>
      <origin rpy="0 0 0" xyz="3.5006E-08 0.0090395 0.033861"/>
      <mass value="0.00001"/>
      <inertia ixx="0.001" ixy="0.0" ixz="0.0" iyy="0.001" iyz="0.0" izz="0.001"/>
    </inertial>
    <visual>
      <origin rpy="0 0 0" xyz="0 0 0"/>
      <geometry>
        <mesh filename="package://le_arm/meshes/arm/forearm_link.STL"/>
      </geometry>
      <material name="">
        <color rgba="0.75294 0.75294 0.75294 1"/>
      </material>
    </visual>
    <collision>
      <origin rpy="0 0 0" xyz="0 0 0"/>
      <geometry>
        <mesh filename="package://le_arm/meshes/arm/forearm_link.STL"/>
      </geometry>
    </collision>
  </link>
  <gazebo reference="forearm_link">
    <implicitSpringDamper>1</implicitSpringDamper>
    <mu1>100000</mu1>
    <mu2>100000</mu2>
    <kp>100000000.0</kp>
    <kd>1.0</kd>
  </gazebo>
  <joint name="elbow_joint" type="revolute">
    <origin rpy="-1.6E-10 0.785 0" xyz="0 -0.0335 0.104"/>
    <parent link="upper_arm_link"/>
    <child link="forearm_link"/>
    <axis xyz="0 -1 0"/>
    <limit effort="1000" lower="-1.57" upper="1.57" velocity="2"/>
  </joint>
  <link name="wrist_1_link">
    <inertial>
      <origin rpy="0 0 0" xyz="-0.010432 0.010212 0.019017"/>
      <mass value="0.00001"/>
      <inertia ixx="0.001" ixy="0.0" ixz="0.0" iyy="0.001" iyz="0.0" izz="0.001"/>
    </inertial>
    <visual>
      <origin rpy="0 0 0" xyz="0 0 0"/>
      <geometry>
        <mesh filename="package://le_arm/meshes/arm/wrist_1_link.STL"/>
      </geometry>
      <material name="">
        <color rgba="0.75294 0.75294 0.75294 1"/>
      </material>
    </visual>
    <collision>
      <origin rpy="0 0 0" xyz="0 0 0"/>
      <geometry>
        <mesh filename="package://le_arm/meshes/arm/wrist_1_link.STL"/>
      </geometry>
    </collision>
  </link>
  <gazebo reference="wrist_1_link">
    <implicitSpringDamper>1</implicitSpringDamper>
    <mu1>100000</mu1>
    <mu2>100000</mu2>
    <kp>100000000.0</kp>
    <kd>1.0</kd>
  </gazebo>
  <joint name="wrist_1_joint" type="revolute">
    <origin rpy="5.3884E-11 0 0" xyz="-0.0007415 0.0054 0.088419"/>
    <parent link="forearm_link"/>
    <child link="wrist_1_link"/>
    <axis xyz="0 -1 0"/>
    <limit effort="1000" lower="-1.57" upper="1.57" velocity="2"/>
  </joint>
  <joint name="wrist_2_joint" type="revolute">
    <origin rpy="0 0 0" xyz="0 0.009 0.059"/>
    <parent link="wrist_1_link"/>
    <child link="gripper_base_link"/>
    <axis xyz="0 0 1"/>
    <limit effort="1000" lower="-1.57" upper="1.57" velocity="2"/>
  </joint>
  <link name="gripper_base_link">
    <inertial>
      <origin rpy="0 0 0" xyz="-0.016093 0.0024206 0.03061"/>
      <mass value="0.00001"/>
      <inertia ixx="0.001" ixy="0.0" ixz="0.0" iyy="0.001" iyz="0.0" izz="0.001"/>
    </inertial>
    <visual>
      <origin rpy="0 0 0" xyz="0 0 0"/>
      <geometry>
        <mesh filename="package://le_arm/meshes/gripper/base_link.STL"/>
      </geometry>
      <material name="">
        <color rgba="0.75294 0.75294 0.75294 1"/>
      </material>
    </visual>
    <collision>
      <origin rpy="0 0 0" xyz="0 0 0"/>
      <geometry>
        <mesh filename="package://le_arm/meshes/gripper/base_link.STL"/>
      </geometry>
    </collision>
  </link>
  <gazebo reference="gripper_base_link">
    <implicitSpringDamper>1</implicitSpringDamper>
    <mu1>100000</mu1>
    <mu2>100000</mu2>
    <kp>100000000.0</kp>
    <kd>1.0</kd>
  </gazebo>
  <link name="left_knuckle_link">
    <inertial>
      <origin rpy="0 0 0" xyz="0.0004174 0.0081181 0.00092142"/>
      <mass value="0.00001"/>
      <inertia ixx="0.001" ixy="0.0" ixz="0.0" iyy="0.001" iyz="0.0" izz="0.001"/>
    </inertial>
    <visual>
      <origin rpy="0 0 0" xyz="0 0 0"/>
      <geometry>
        <mesh filename="package://le_arm/meshes/gripper/left_knuckle_link.STL"/>
      </geometry>
      <material name="">
        <color rgba="0.75294 0.75294 0.75294 1"/>
      </material>
    </visual>
    <collision>
      <origin rpy="0 0 0" xyz="0 0 0"/>
      <geometry>
        <mesh filename="package://le_arm/meshes/gripper/left_knuckle_link.STL"/>
      </geometry>
    </collision>
  </link>
  <gazebo reference="left_knuckle_link">
    <implicitSpringDamper>1</implicitSpringDamper>
    <mu1>100000</mu1>
    <mu2>100000</mu2>
    <kp>100000000.0</kp>
    <kd>1.0</kd>
  </gazebo>
  <joint name="left_knuckle_joint" type="revolute">
    <origin rpy="1.5708 -0.59692 1.5708" xyz="0.0045 -0.014 0.0325"/>
    <parent link="gripper_base_link"/>
    <child link="left_knuckle_link"/>
    <axis xyz="0 0 1"/>
    <limit effort="1000" lower="-1.57" upper="1.57" velocity="2.0"/>
  </joint>
  <link name="right_knuckle_link">
    <inertial>
      <origin rpy="0 0 0" xyz="0.00045059 0.0080041 0.0020288"/>
      <mass value="0.00001"/>
      <inertia ixx="0.001" ixy="0.0" ixz="0.0" iyy="0.001" iyz="0.0" izz="0.001"/>
    </inertial>
    <visual>
      <origin rpy="0 0 0" xyz="0 0 0"/>
      <geometry>
        <mesh filename="package://le_arm/meshes/gripper/right_knuckle_link.STL"/>
      </geometry>
      <material name="">
        <color rgba="0.75294 0.75294 0.75294 1"/>
      </material>
    </visual>
    <collision>
      <origin rpy="0 0 0" xyz="0 0 0"/>
      <geometry>
        <mesh filename="package://le_arm/meshes/gripper/right_knuckle_link.STL"/>
      </geometry>
    </collision>
  </link>
  <gazebo reference="right_knuckle_link">
    <implicitSpringDamper>1</implicitSpringDamper>
    <mu1>100000</mu1>
    <mu2>100000</mu2>
    <kp>100000000.0</kp>
    <kd>1.0</kd>
  </gazebo>
  <joint name="right_knuckle_joint" type="revolute">
    <origin rpy="1.5708 -0.69513 -1.5708" xyz="0.0075 0.014 0.0325"/>
    <parent link="gripper_base_link"/>
    <child link="right_knuckle_link"/>
    <axis xyz="0 0 -1"/>
    <limit effort="1000" lower="-1.57" upper="1.57" velocity="2.0"/>
    <mimic joint="left_knuckle_joint" multiplier="-1"/>
  </joint>
  <link name="left_inner_knuckle_link">
    <inertial>
      <origin rpy="0 0 0" xyz="-0.013801 1.3512E-10 -0.0091952"/>
      <mass value="0.00001"/>
      <inertia ixx="0.001" ixy="0.0" ixz="0.0" iyy="0.001" iyz="0.0" izz="0.001"/>
    </inertial>
    <visual>
      <origin rpy="0 0 0" xyz="0 0 0"/>
      <geometry>
        <mesh filename="package://le_arm/meshes/gripper/left_inner_knuckle_link.STL"/>
      </geometry>
      <material name="">
        <color rgba="0.75294 0.75294 0.75294 1"/>
      </material>
    </visual>
    <collision>
      <origin rpy="0 0 0" xyz="0 0 0"/>
      <geometry>
        <mesh filename="package://le_arm/meshes/gripper/left_inner_knuckle_link.STL"/>
      </geometry>
    </collision>
  </link>
  <gazebo reference="left_inner_knuckle_link">
    <implicitSpringDamper>1</implicitSpringDamper>
    <mu1>100000</mu1>
    <mu2>100000</mu2>
    <kp>100000000.0</kp>
    <kd>1.0</kd>
  </gazebo>
  <joint name="left_inner_knuckle_joint" type="revolute">
    <origin rpy="1.5708 0.97387 1.5708" xyz="0.0099 -0.005 0.051474"/>
    <parent link="gripper_base_link"/>
    <child link="left_inner_knuckle_link"/>
    <axis xyz="0 0 1"/>
    <limit effort="1000" lower="-1.57" upper="1.57" velocity="2.0"/>
    <mimic joint="left_knuckle_joint" multiplier="1"/>
  </joint>
  <link name="left_finger_link">
    <inertial>
      <origin rpy="0 0 0" xyz="-0.0038459 0.0027734 -5.6082E-05"/>
      <mass value="0.00001"/>
      <inertia ixx="0.001" ixy="0.0" ixz="0.0" iyy="0.001" iyz="0.0" izz="0.001"/>
    </inertial>
    <visual>
      <origin rpy="0 0 0" xyz="0 0 0"/>
      <geometry>
        <mesh filename="package://le_arm/meshes/gripper/left_finger_link.STL"/>
      </geometry>
      <material name="">
        <color rgba="0.75294 0.75294 0.75294 1"/>
      </material>
    </visual>
    <collision>
      <origin rpy="0 0 0" xyz="0 0 0"/>
      <geometry>
        <mesh filename="package://le_arm/meshes/gripper/left_finger_link.STL"/>
      </geometry>
    </collision>
  </link>
  <gazebo reference="left_finger_link">
    <implicitSpringDamper>1</implicitSpringDamper>
    <mu1>100000</mu1>
    <mu2>100000</mu2>
    <kp>100000000.0</kp>
    <kd>1.0</kd>
  </gazebo>
  <joint name="left_finger_joint" type="revolute">
    <origin rpy="9.0533E-10 -1.7902E-09 0.53096" xyz="-0.029 0 -0.0084"/>
    <parent link="left_inner_knuckle_link"/>
    <child link="left_finger_link"/>
    <axis xyz="0 0 1"/>
    <limit effort="1000" lower="-1.57" upper="1.57" velocity="2.0"/>
    <mimic joint="left_knuckle_joint" multiplier="-1"/>
  </joint>
  <link name="right_inner_knuckle_link">
    <inertial>
      <origin rpy="0 0 0" xyz="-0.013801 4.8285E-11 0.0069248"/>
      <mass value="0.00001"/>
      <inertia ixx="0.001" ixy="0.0" ixz="0.0" iyy="0.001" iyz="0.0" izz="0.001"/>
    </inertial>
    <visual>
      <origin rpy="0 0 0" xyz="0 0 0"/>
      <geometry>
        <mesh filename="package://le_arm/meshes/gripper/right_inner_knuckle_link.STL"/>
      </geometry>
      <material name="">
        <color rgba="0.75294 0.75294 0.75294 1"/>
      </material>
    </visual>
    <collision>
      <origin rpy="0 0 0" xyz="0 0 0"/>
      <geometry>
        <mesh filename="package://le_arm/meshes/gripper/right_inner_knuckle_link.STL"/>
      </geometry>
    </collision>
  </link>
  <gazebo reference="right_inner_knuckle_link">
    <implicitSpringDamper>1</implicitSpringDamper>
    <mu1>100000</mu1>
    <mu2>100000</mu2>
    <kp>100000000.0</kp>
    <kd>1.0</kd>
  </gazebo>
  <joint name="right_inner_knuckle_joint" type="revolute">
    <origin rpy="-1.5708 0.87566 -1.5708" xyz="-0.00622 0.005 0.051474"/>
    <parent link="gripper_base_link"/>
    <child link="right_inner_knuckle_link"/>
    <axis xyz="0 0 1"/>
    <limit effort="1000" lower="-1.57" upper="1.57" velocity="2.0"/>
    <mimic joint="left_knuckle_joint" multiplier="-1"/>
  </joint>
  <link name="right_finger_link">
    <inertial>
      <origin rpy="0 0 0" xyz="-0.0038459 0.0027734 0.0030561"/>
      <mass value="0.00001"/>
      <inertia ixx="0.001" ixy="0.0" ixz="0.0" iyy="0.001" iyz="0.0" izz="0.001"/>
    </inertial>
    <visual>
      <origin rpy="0 0 0" xyz="0 0 0"/>
      <geometry>
        <mesh filename="package://le_arm/meshes/gripper/right_finger_link.STL"/>
      </geometry>
      <material name="">
        <color rgba="0.75294 0.75294 0.75294 1"/>
      </material>
    </visual>
    <collision>
      <origin rpy="0 0 0" xyz="0 0 0"/>
      <geometry>
        <mesh filename="package://le_arm/meshes/gripper/right_finger_link.STL"/>
      </geometry>
    </collision>
  </link>
  <gazebo reference="right_finger_link">
    <implicitSpringDamper>1</implicitSpringDamper>
    <mu1>100000</mu1>
    <mu2>100000</mu2>
    <kp>100000000.0</kp>
    <kd>1.0</kd>
  </gazebo>
  <joint name="right_finger_joint" type="revolute">
    <origin rpy="-3.1416 1.7902E-09 -0.43275" xyz="-0.029 0 0.01072"/>
    <parent link="right_inner_knuckle_link"/>
    <child link="right_finger_link"/>
    <axis xyz="0 0 -1"/>
    <limit effort="1000" lower="-1.57" upper="1.57" velocity="2.0"/>
    <mimic joint="left_knuckle_joint" multiplier="1"/>
  </joint>
  <transmission name="wrist_2_transmission">
    <type>transmission_interface/SimpleTransmission</type>
    <joint name="wrist_2_joint">
      <hardwareInterface>hardware_interface/PositionJointInterface</hardwareInterface>
    </joint>
    <actuator name="wrist_2_motor">
      <mechanicalReduction>1</mechanicalReduction>
      <hardwareInterface>hardware_interface/PositionJointInterface</hardwareInterface>
    </actuator>
  </transmission>
  <transmission name="left_knuckle_joint_transmission">
    <type>transmission_interface/SimpleTransmission</type>
    <joint name="left_knuckle_joint">
      <hardwareInterface>hardware_interface/PositionJointInterface</hardwareInterface>
    </joint>
    <actuator name="left_knuckle_motor">
      <mechanicalReduction>1</mechanicalReduction>
      <hardwareInterface>hardware_interface/PositionJointInterface</hardwareInterface>
    </actuator>
  </transmission>
  <gazebo>
    <plugin filename="libroboticsgroup_gazebo_mimic_joint_plugin.so" name="MimicJointPlugin_right_finger">
      <joint>left_knuckle_joint</joint>
      <mimicJoint>right_finger_joint</mimicJoint>
    </plugin>
    <plugin filename="libroboticsgroup_gazebo_mimic_joint_plugin.so" name="MimicJointPlugin_right_inner_knuckle">
      <joint>left_knuckle_joint</joint>
      <mimicJoint>right_inner_knuckle_joint</mimicJoint>
      <multiplier>-1</multiplier>
      <offset>0.0</offset>
    </plugin>
    <plugin filename="libroboticsgroup_gazebo_mimic_joint_plugin.so" name="MimicJointPlugin_left_finger">
      <joint>left_knuckle_joint</joint>
      <mimicJoint>left_finger_joint</mimicJoint>
      <multiplier>-1</multiplier>
      <offset>0.0</offset>
    </plugin>
    <plugin filename="libroboticsgroup_gazebo_mimic_joint_plugin.so" name="MimicJointPlugin_left_inner_knuckle">
      <joint>left_knuckle_joint</joint>
      <mimicJoint>left_inner_knuckle_joint</mimicJoint>
    </plugin>
    <plugin filename="libroboticsgroup_gazebo_mimic_joint_plugin.so" name="Mimic_right_knuckle">
      <joint>left_knuckle_joint</joint>
      <mimicJoint>right_knuckle_joint</mimicJoint>
      <multiplier>-1</multiplier>
      <offset>0.0</offset>
    </plugin>
  </gazebo>
  <transmission name="shoulder_pan_trans">
    <type>transmission_interface/SimpleTransmission</type>
    <joint name="shoulder_pan_joint">
      <hardwareInterface>hardware_interface/PositionJointInterface</hardwareInterface>
    </joint>
    <actuator name="shoulder_pan_motor">
      <mechanicalReduction>1</mechanicalReduction>
      <hardwareInterface>hardware_interface/PositionJointInterface</hardwareInterface>
    </actuator>
  </transmission>
  <transmission name="shoulder_lift_trans">
    <type>transmission_interface/SimpleTransmission</type>
    <joint name="shoulder_lift_joint">
      <hardwareInterface>hardware_interface/PositionJointInterface</hardwareInterface>
    </joint>
    <actuator name="shoulder_lift_motor">
      <mechanicalReduction>1</mechanicalReduction>
      <hardwareInterface>hardware_interface/PositionJointInterface</hardwareInterface>
    </actuator>
  </transmission>
  <transmission name="elbow_trans">
    <type>transmission_interface/SimpleTransmission</type>
    <joint name="elbow_joint">
      <hardwareInterface>hardware_interface/PositionJointInterface</hardwareInterface>
    </joint>
    <actuator name="elbow_motor">
      <mechanicalReduction>1</mechanicalReduction>
      <hardwareInterface>hardware_interface/PositionJointInterface</hardwareInterface>
    </actuator>
  </transmission>
  <transmission name="wrist_1_trans">
    <type>transmission_interface/SimpleTransmission</type>
    <joint name="wrist_1_joint">
      <hardwareInterface>hardware_interface/PositionJointInterface</hardwareInterface>
    </joint>
    <actuator name="wrist_1_motor">
      <mechanicalReduction>1</mechanicalReduction>
      <hardwareInterface>hardware_interface/PositionJointInterface</hardwareInterface>
    </actuator>
  </transmission>
</robot>

