<?xml version="1.0" encoding="utf-8"?>
<!-- =================================================================================== -->
<!-- |    This document was autogenerated by xacro from iris_arm_base.xacro            | -->
<!-- |    EDITING THIS FILE BY HAND IS NOT RECOMMENDED                                 | -->
<!-- =================================================================================== -->
<robot name="iris">
  <!-- =============================================================== -->
  <!-- ==================== ROS INTERFACE MACRO ====================== -->
  <!-- =============================================================== -->
  <!-- <xacro:macro 
  		name="ros_interface_plugin_macro"
  		params="namespace">
    <gazebo>
      <plugin name="ros_interface_plugin" filename="librotors_gazebo_ros_interface_plugin.so">
        <robotNamespace>${namespace}</robotNamespace>
      </plugin>
    </gazebo>
  </xacro:macro>-->
  <link name="base_link">
    <collision>
      <origin rpy="0 0 0" xyz="0.123 0.22 -0.12"/>
      <geometry>
        <cylinder length="0.3" radius="0.005"/>
      </geometry>
    </collision>
    <visual>
      <origin rpy="0 0 0" xyz="0.123 0.22 -0.12"/>
      <geometry>
        <cylinder length="0.3" radius="0.005"/>
      </geometry>
    </visual>
    <collision>
      <origin rpy="0 0 0" xyz="0.123 -0.22 -0.12"/>
      <geometry>
        <cylinder length="0.3" radius="0.005"/>
      </geometry>
    </collision>
    <visual>
      <origin rpy="0 0 0" xyz="0.123 -0.22 -0.12"/>
      <geometry>
        <cylinder length="0.3" radius="0.005"/>
      </geometry>
    </visual>
    <collision>
      <origin rpy="0 0 0" xyz="-0.140 0.21 -0.12"/>
      <geometry>
        <cylinder length="0.3" radius="0.005"/>
      </geometry>
    </collision>
    <visual>
      <origin rpy="0 0 0" xyz="-0.140 0.21 -0.12"/>
      <geometry>
        <cylinder length="0.3" radius="0.005"/>
      </geometry>
    </visual>
    <collision>
      <origin rpy="0 0 0" xyz="-0.140 -0.21 -0.12"/>
      <geometry>
        <cylinder length="0.3" radius="0.005"/>
      </geometry>
    </collision>
    <visual>
      <origin rpy="0 0 0" xyz="-0.140 -0.21 -0.12"/>
      <geometry>
        <cylinder length="0.3" radius="0.005"/>
      </geometry>
    </visual>
  </link>
  <joint name="base_joint" type="fixed">
    <origin rpy="0 0 0" xyz="0 0 0"/>
    <parent link="base_link"/>
    <child link="base_link_inertia"/>
  </joint>
  <link name="base_link_inertia">
    <inertial>
      <mass value="1.5"/>
      <!-- [kg] -->
      <origin xyz="0 0 0"/>
      <inertia ixx="0.029125" ixy="0.0" ixz="0.0" iyy="0.029125" iyz="0.0" izz="0.055225"/>
    </inertial>
    <visual>
      <origin rpy="0 0 0" xyz="0 0 0"/>
      <geometry>
        <mesh filename="package://le_arm/meshes/iris/iris.stl" scale="1 1 1"/>
        <!-- <box size="${body_width} ${body_width} ${body_height}"/> -->
        <!-- [m] [m] [m] -->
      </geometry>
    </visual>
    <collision>
      <origin rpy="0 0 0" xyz="0 0 0"/>
      <geometry>
        <box size="0.47 0.47 0.11"/>
        <!-- [m] [m] [m] -->
      </geometry>
    </collision>
  </link>
  <!-- attach multirotor_base_plugin to the base_link -->
  <gazebo>
    <plugin filename="libgazebo_multirotor_base_plugin.so" name="rosbag">
      <robotNamespace></robotNamespace>
      <linkName>base_link</linkName>
      <rotorVelocitySlowdownSim>10</rotorVelocitySlowdownSim>
    </plugin>
  </gazebo>
  <gazebo reference="base_link">
    <material>Gazebo/DarkGrey</material>
    <collision name="base_link_inertia_collision">
      <surface>
        <contact>
          <ode>
            <min_depth>0.001</min_depth>
            <max_vel>0.0</max_vel>
          </ode>
        </contact>
        <friction>
          <ode/>
        </friction>
      </surface>
    </collision>
  </gazebo>
  <joint name="rotor_0_joint" type="continuous">
    <origin rpy="0 0 0" xyz="0.13 -0.22 0.023"/>
    <axis xyz="0 0 1"/>
    <!-- TODO(ff): not currently set because it's not yet supported -->
    <!-- <limit effort="2000" velocity="${max_rot_velocity}" /> -->
    <parent link="base_link"/>
    <child link="rotor_0"/>
  </joint>
  <!-- TODO(ff): not currently set because it's not yet supported -->
  <!-- <gazebo reference="rotor_${motor_number}_joint"> <axis> <xyz>0 0 1</xyz>
      <limit> <velocity> ${max_rot_velocity} </velocity> </limit> </axis> </gazebo> -->
  <link name="rotor_0">
    <inertial>
      <mass value="0.005"/>
      <!-- [kg] -->
      <inertia ixx="9.75e-07" ixy="0.0" ixz="0.0" iyy="0.000273104166667" iyz="0.0" izz="0.000274004166667"/>
    </inertial>
    <visual>
      <geometry>
        <!-- <cylinder length="0.005" radius="${radius_rotor}"/> -->
        <!-- [m] -->
        <!-- <mesh filename="package://le_arm/meshes/propeller_${direction}.dae" -->
        <mesh filename="package://le_arm/meshes/iris/iris_prop_ccw.dae" scale="1 1 1"/>
        <!-- <box size="${2*radius_rotor} 0.01 0.005"/> -->
      </geometry>
    </visual>
    <collision>
      <geometry>
        <cylinder length="0.005" radius="0.128"/>
        <!-- [m] -->
      </geometry>
    </collision>
  </link>
  <gazebo>
    <plugin filename="libgazebo_motor_model.so" name="front_right_motor_model">
      <robotNamespace></robotNamespace>
      <jointName>rotor_0_joint</jointName>
      <linkName>rotor_0</linkName>
      <turningDirection>ccw</turningDirection>
      <timeConstantUp>0.0125</timeConstantUp>
      <timeConstantDown>0.025</timeConstantDown>
      <maxRotVelocity>1100</maxRotVelocity>
      <motorConstant>8.54858e-06</motorConstant>
      <momentConstant>0.06</momentConstant>
      <commandSubTopic>/gazebo/command/motor_speed</commandSubTopic>
      <motorNumber>0</motorNumber>
      <rotorDragCoefficient>0.000175</rotorDragCoefficient>
      <rollingMomentCoefficient>1e-06</rollingMomentCoefficient>
      <motorSpeedPubTopic>/motor_speed/0</motorSpeedPubTopic>
      <rotorVelocitySlowdownSim>10</rotorVelocitySlowdownSim>
      <!--
        <gazebo_joint_control_pid>
          <p>0.1</p>
          <i>0</i>
          <d>0</d>
          <iMax>0</iMax>
          <iMin>0</iMin>
          <cmdMax>3</cmdMax>
          <cmdMin>-3</cmdMin>
        </gazebo_joint_control_pid>
      -->
    </plugin>
  </gazebo>
  <gazebo reference="rotor_0">
    <material>Gazebo/Blue</material>
  </gazebo>
  <joint name="rotor_1_joint" type="continuous">
    <origin rpy="0 0 0" xyz="-0.13 0.2 0.023"/>
    <axis xyz="0 0 1"/>
    <!-- TODO(ff): not currently set because it's not yet supported -->
    <!-- <limit effort="2000" velocity="${max_rot_velocity}" /> -->
    <parent link="base_link"/>
    <child link="rotor_1"/>
  </joint>
  <!-- TODO(ff): not currently set because it's not yet supported -->
  <!-- <gazebo reference="rotor_${motor_number}_joint"> <axis> <xyz>0 0 1</xyz>
      <limit> <velocity> ${max_rot_velocity} </velocity> </limit> </axis> </gazebo> -->
  <link name="rotor_1">
    <inertial>
      <mass value="0.005"/>
      <!-- [kg] -->
      <inertia ixx="9.75e-07" ixy="0.0" ixz="0.0" iyy="0.000273104166667" iyz="0.0" izz="0.000274004166667"/>
    </inertial>
    <visual>
      <geometry>
        <!-- <cylinder length="0.005" radius="${radius_rotor}"/> -->
        <!-- [m] -->
        <!-- <mesh filename="package://le_arm/meshes/propeller_${direction}.dae" -->
        <mesh filename="package://le_arm/meshes/iris/iris_prop_ccw.dae" scale="1 1 1"/>
        <!-- <box size="${2*radius_rotor} 0.01 0.005"/> -->
      </geometry>
    </visual>
    <collision>
      <geometry>
        <cylinder length="0.005" radius="0.128"/>
        <!-- [m] -->
      </geometry>
    </collision>
  </link>
  <gazebo>
    <plugin filename="libgazebo_motor_model.so" name="back_left_motor_model">
      <robotNamespace></robotNamespace>
      <jointName>rotor_1_joint</jointName>
      <linkName>rotor_1</linkName>
      <turningDirection>ccw</turningDirection>
      <timeConstantUp>0.0125</timeConstantUp>
      <timeConstantDown>0.025</timeConstantDown>
      <maxRotVelocity>1100</maxRotVelocity>
      <motorConstant>8.54858e-06</motorConstant>
      <momentConstant>0.06</momentConstant>
      <commandSubTopic>/gazebo/command/motor_speed</commandSubTopic>
      <motorNumber>1</motorNumber>
      <rotorDragCoefficient>0.000175</rotorDragCoefficient>
      <rollingMomentCoefficient>1e-06</rollingMomentCoefficient>
      <motorSpeedPubTopic>/motor_speed/1</motorSpeedPubTopic>
      <rotorVelocitySlowdownSim>10</rotorVelocitySlowdownSim>
      <!--
        <gazebo_joint_control_pid>
          <p>0.1</p>
          <i>0</i>
          <d>0</d>
          <iMax>0</iMax>
          <iMin>0</iMin>
          <cmdMax>3</cmdMax>
          <cmdMin>-3</cmdMin>
        </gazebo_joint_control_pid>
      -->
    </plugin>
  </gazebo>
  <gazebo reference="rotor_1">
    <material>Gazebo/DarkGrey</material>
  </gazebo>
  <joint name="rotor_2_joint" type="continuous">
    <origin rpy="0 0 0" xyz="0.13 0.22 0.023"/>
    <axis xyz="0 0 1"/>
    <!-- TODO(ff): not currently set because it's not yet supported -->
    <!-- <limit effort="2000" velocity="${max_rot_velocity}" /> -->
    <parent link="base_link"/>
    <child link="rotor_2"/>
  </joint>
  <!-- TODO(ff): not currently set because it's not yet supported -->
  <!-- <gazebo reference="rotor_${motor_number}_joint"> <axis> <xyz>0 0 1</xyz>
      <limit> <velocity> ${max_rot_velocity} </velocity> </limit> </axis> </gazebo> -->
  <link name="rotor_2">
    <inertial>
      <mass value="0.005"/>
      <!-- [kg] -->
      <inertia ixx="9.75e-07" ixy="0.0" ixz="0.0" iyy="0.000273104166667" iyz="0.0" izz="0.000274004166667"/>
    </inertial>
    <visual>
      <geometry>
        <!-- <cylinder length="0.005" radius="${radius_rotor}"/> -->
        <!-- [m] -->
        <!-- <mesh filename="package://le_arm/meshes/propeller_${direction}.dae" -->
        <mesh filename="package://le_arm/meshes/iris/iris_prop_cw.dae" scale="1 1 1"/>
        <!-- <box size="${2*radius_rotor} 0.01 0.005"/> -->
      </geometry>
    </visual>
    <collision>
      <geometry>
        <cylinder length="0.005" radius="0.128"/>
        <!-- [m] -->
      </geometry>
    </collision>
  </link>
  <gazebo>
    <plugin filename="libgazebo_motor_model.so" name="front_left_motor_model">
      <robotNamespace></robotNamespace>
      <jointName>rotor_2_joint</jointName>
      <linkName>rotor_2</linkName>
      <turningDirection>cw</turningDirection>
      <timeConstantUp>0.0125</timeConstantUp>
      <timeConstantDown>0.025</timeConstantDown>
      <maxRotVelocity>1100</maxRotVelocity>
      <motorConstant>8.54858e-06</motorConstant>
      <momentConstant>0.06</momentConstant>
      <commandSubTopic>/gazebo/command/motor_speed</commandSubTopic>
      <motorNumber>2</motorNumber>
      <rotorDragCoefficient>0.000175</rotorDragCoefficient>
      <rollingMomentCoefficient>1e-06</rollingMomentCoefficient>
      <motorSpeedPubTopic>/motor_speed/2</motorSpeedPubTopic>
      <rotorVelocitySlowdownSim>10</rotorVelocitySlowdownSim>
      <!--
        <gazebo_joint_control_pid>
          <p>0.1</p>
          <i>0</i>
          <d>0</d>
          <iMax>0</iMax>
          <iMin>0</iMin>
          <cmdMax>3</cmdMax>
          <cmdMin>-3</cmdMin>
        </gazebo_joint_control_pid>
      -->
    </plugin>
  </gazebo>
  <gazebo reference="rotor_2">
    <material>Gazebo/Blue</material>
  </gazebo>
  <joint name="rotor_3_joint" type="continuous">
    <origin rpy="0 0 0" xyz="-0.13 -0.2 0.023"/>
    <axis xyz="0 0 1"/>
    <!-- TODO(ff): not currently set because it's not yet supported -->
    <!-- <limit effort="2000" velocity="${max_rot_velocity}" /> -->
    <parent link="base_link"/>
    <child link="rotor_3"/>
  </joint>
  <!-- TODO(ff): not currently set because it's not yet supported -->
  <!-- <gazebo reference="rotor_${motor_number}_joint"> <axis> <xyz>0 0 1</xyz>
      <limit> <velocity> ${max_rot_velocity} </velocity> </limit> </axis> </gazebo> -->
  <link name="rotor_3">
    <inertial>
      <mass value="0.005"/>
      <!-- [kg] -->
      <inertia ixx="9.75e-07" ixy="0.0" ixz="0.0" iyy="0.000273104166667" iyz="0.0" izz="0.000274004166667"/>
    </inertial>
    <visual>
      <geometry>
        <!-- <cylinder length="0.005" radius="${radius_rotor}"/> -->
        <!-- [m] -->
        <!-- <mesh filename="package://le_arm/meshes/propeller_${direction}.dae" -->
        <mesh filename="package://le_arm/meshes/iris/iris_prop_cw.dae" scale="1 1 1"/>
        <!-- <box size="${2*radius_rotor} 0.01 0.005"/> -->
      </geometry>
    </visual>
    <collision>
      <geometry>
        <cylinder length="0.005" radius="0.128"/>
        <!-- [m] -->
      </geometry>
    </collision>
  </link>
  <gazebo>
    <plugin filename="libgazebo_motor_model.so" name="back_right_motor_model">
      <robotNamespace></robotNamespace>
      <jointName>rotor_3_joint</jointName>
      <linkName>rotor_3</linkName>
      <turningDirection>cw</turningDirection>
      <timeConstantUp>0.0125</timeConstantUp>
      <timeConstantDown>0.025</timeConstantDown>
      <maxRotVelocity>1100</maxRotVelocity>
      <motorConstant>8.54858e-06</motorConstant>
      <momentConstant>0.06</momentConstant>
      <commandSubTopic>/gazebo/command/motor_speed</commandSubTopic>
      <motorNumber>3</motorNumber>
      <rotorDragCoefficient>0.000175</rotorDragCoefficient>
      <rollingMomentCoefficient>1e-06</rollingMomentCoefficient>
      <motorSpeedPubTopic>/motor_speed/3</motorSpeedPubTopic>
      <rotorVelocitySlowdownSim>10</rotorVelocitySlowdownSim>
      <!--
        <gazebo_joint_control_pid>
          <p>0.1</p>
          <i>0</i>
          <d>0</d>
          <iMax>0</iMax>
          <iMin>0</iMin>
          <cmdMax>3</cmdMax>
          <cmdMin>-3</cmdMin>
        </gazebo_joint_control_pid>
      -->
    </plugin>
  </gazebo>
  <gazebo reference="rotor_3">
    <material>Gazebo/DarkGrey</material>
  </gazebo>
  <gazebo>
    <plugin filename="libgazebo_ros_control.so" name="gazebo_ros_control">
      <robotNamespace>/</robotNamespace>
    </plugin>
  </gazebo>
  <joint name="arm_base_joint" type="fixed">
    <parent link="base_link"/>
    <child link="arm_base_link"/>
    <origin rpy="0 3.14 3.14" xyz="-0.1 0 -0.05"/>
  </joint>
  <link name="arm_base_link">
    <inertial>
      <origin rpy="0 0 0" xyz="0.034411 3.2244E-06 0.02029"/>
      <mass value="0.00001"/>
      <inertia ixx="0.001" ixy="0.0" ixz="0.0" iyy="0.001" iyz="0.0" izz="0.001"/>
    </inertial>
    <visual>
      <origin rpy="0 0 0" xyz="0 0 0"/>
      <geometry>
        <mesh filename="package://le_arm/meshes/arm/base_link.STL"/>
      </geometry>
      <material name="">
        <color rgba="0.75294 0.75294 0.75294 1"/>
      </material>
    </visual>
    <collision>
      <origin rpy="0 0 0" xyz="0 0 0"/>
      <geometry>
        <mesh filename="package://le_arm/meshes/arm/base_link.STL"/>
      </geometry>
    </collision>
  </link>
  <gazebo reference="arm_base_link">
    <implicitSpringDamper>1</implicitSpringDamper>
    <mu1>100000</mu1>
    <mu2>100000</mu2>
    <kp>100000000.0</kp>
    <kd>1.0</kd>
  </gazebo>
  <link name="shoulder_link">
    <inertial>
      <origin rpy="0 0 0" xyz="-0.0005946 -0.00090913 0.017195"/>
      <mass value="0.00001"/>
      <inertia ixx="0.001" ixy="0.0" ixz="0.0" iyy="0.001" iyz="0.0" izz="0.001"/>
    </inertial>
    <visual>
      <origin rpy="0 0 0" xyz="0 0 0"/>
      <geometry>
        <mesh filename="package://le_arm/meshes/arm/shoulder_link.STL"/>
      </geometry>
      <material name="">
        <color rgba="0.75294 0.75294 0.75294 1"/>
      </material>
    </visual>
    <collision>
      <origin rpy="0 0 0" xyz="0 0 0"/>
      <geometry>
        <mesh filename="package://le_arm/meshes/arm/shoulder_link.STL"/>
      </geometry>
    </collision>
  </link>
  <gazebo reference="shoulder_link">
    <implicitSpringDamper>1</implicitSpringDamper>
    <mu1>100000</mu1>
    <mu2>100000</mu2>
    <kp>100000000.0</kp>
    <kd>1.0</kd>
  </gazebo>
  <joint name="shoulder_pan_joint" type="revolute">
    <origin rpy="1.2297E-10 2.2825E-27 -3.4694E-17" xyz="0.0005 0 0.0535"/>
    <parent link="arm_base_link"/>
    <child link="shoulder_link"/>
    <axis xyz="0 0 1"/>
    <limit effort="1000" lower="-1.57" upper="1.57" velocity="2"/>
  </joint>
  <link name="upper_arm_link">
    <inertial>
      <origin rpy="0 0 0" xyz="2.6345E-08 -0.02405 0.05197"/>
      <mass value="0.00001"/>
      <inertia ixx="0.001" ixy="0.0" ixz="0.0" iyy="0.001" iyz="0.0" izz="0.001"/>
    </inertial>
    <visual>
      <origin rpy="0 0 0" xyz="0 0 0"/>
      <geometry>
        <mesh filename="package://le_arm/meshes/arm/upper_arm_link.STL"/>
      </geometry>
      <material name="">
        <color rgba="0.75294 0.75294 0.75294 1"/>
      </material>
    </visual>
    <collision>
      <origin rpy="0 0 0" xyz="0 0 0"/>
      <geometry>
        <mesh filename="package://le_arm/meshes/arm/upper_arm_link.STL"/>
      </geometry>
    </collision>
  </link>
  <gazebo reference="upper_arm_link">
    <implicitSpringDamper>1</implicitSpringDamper>
    <mu1>100000</mu1>
    <mu2>100000</mu2>
    <kp>100000000.0</kp>
    <kd>1.0</kd>
  </gazebo>
  <joint name="shoulder_lift_joint" type="revolute">
    <origin rpy="-5.7183E-11 0.785 0" xyz="-0.0105 0.0226 0.032"/>
    <parent link="shoulder_link"/>
    <child link="upper_arm_link"/>
    <axis xyz="0 -1 0"/>
    <limit effort="1000" lower="-1.57" upper="1.57" velocity="2"/>
  </joint>
  <link name="forearm_link">
    <inertial>
      <origin rpy="0 0 0" xyz="3.5006E-08 0.0090395 0.033861"/>
      <mass value="0.00001"/>
      <inertia ixx="0.001" ixy="0.0" ixz="0.0" iyy="0.001" iyz="0.0" izz="0.001"/>
    </inertial>
    <visual>
      <origin rpy="0 0 0" xyz="0 0 0"/>
      <geometry>
        <mesh filename="package://le_arm/meshes/arm/forearm_link.STL"/>
      </geometry>
      <material name="">
        <color rgba="0.75294 0.75294 0.75294 1"/>
      </material>
    </visual>
    <collision>
      <origin rpy="0 0 0" xyz="0 0 0"/>
      <geometry>
        <mesh filename="package://le_arm/meshes/arm/forearm_link.STL"/>
      </geometry>
    </collision>
  </link>
  <gazebo reference="forearm_link">
    <implicitSpringDamper>1</implicitSpringDamper>
    <mu1>100000</mu1>
    <mu2>100000</mu2>
    <kp>100000000.0</kp>
    <kd>1.0</kd>
  </gazebo>
  <joint name="elbow_joint" type="revolute">
    <origin rpy="-1.6E-10 0.785 0" xyz="0 -0.0335 0.104"/>
    <parent link="upper_arm_link"/>
    <child link="forearm_link"/>
    <axis xyz="0 -1 0"/>
    <limit effort="1000" lower="-1.57" upper="1.57" velocity="2"/>
  </joint>
  <link name="wrist_1_link">
    <inertial>
      <origin rpy="0 0 0" xyz="-0.010432 0.010212 0.019017"/>
      <mass value="0.00001"/>
      <inertia ixx="0.001" ixy="0.0" ixz="0.0" iyy="0.001" iyz="0.0" izz="0.001"/>
    </inertial>
    <visual>
      <origin rpy="0 0 0" xyz="0 0 0"/>
      <geometry>
        <mesh filename="package://le_arm/meshes/arm/wrist_1_link.STL"/>
      </geometry>
      <material name="">
        <color rgba="0.75294 0.75294 0.75294 1"/>
      </material>
    </visual>
    <collision>
      <origin rpy="0 0 0" xyz="0 0 0"/>
      <geometry>
        <mesh filename="package://le_arm/meshes/arm/wrist_1_link.STL"/>
      </geometry>
    </collision>
  </link>
  <gazebo reference="wrist_1_link">
    <implicitSpringDamper>1</implicitSpringDamper>
    <mu1>100000</mu1>
    <mu2>100000</mu2>
    <kp>100000000.0</kp>
    <kd>1.0</kd>
  </gazebo>
  <joint name="wrist_1_joint" type="revolute">
    <origin rpy="5.3884E-11 0 0" xyz="-0.0007415 0.0054 0.088419"/>
    <parent link="forearm_link"/>
    <child link="wrist_1_link"/>
    <axis xyz="0 -1 0"/>
    <limit effort="1000" lower="-1.57" upper="1.57" velocity="2"/>
  </joint>
  <joint name="wrist_2_joint" type="revolute">
    <origin rpy="0 0 0" xyz="0 0.009 0.059"/>
    <parent link="wrist_1_link"/>
    <child link="gripper_base_link"/>
    <axis xyz="0 0 1"/>
    <limit effort="1000" lower="-1.57" upper="1.57" velocity="2"/>
  </joint>
  <link name="gripper_base_link">
    <inertial>
      <origin rpy="0 0 0" xyz="-0.016093 0.0024206 0.03061"/>
      <mass value="0.00001"/>
      <inertia ixx="0.001" ixy="0.0" ixz="0.0" iyy="0.001" iyz="0.0" izz="0.001"/>
    </inertial>
    <visual>
      <origin rpy="0 0 0" xyz="0 0 0"/>
      <geometry>
        <mesh filename="package://le_arm/meshes/gripper/base_link.STL"/>
      </geometry>
      <material name="">
        <color rgba="0.75294 0.75294 0.75294 1"/>
      </material>
    </visual>
    <collision>
      <origin rpy="0 0 0" xyz="0 0 0"/>
      <geometry>
        <mesh filename="package://le_arm/meshes/gripper/base_link.STL"/>
      </geometry>
    </collision>
  </link>
  <gazebo reference="gripper_base_link">
    <implicitSpringDamper>1</implicitSpringDamper>
    <mu1>100000</mu1>
    <mu2>100000</mu2>
    <kp>100000000.0</kp>
    <kd>1.0</kd>
  </gazebo>
  <link name="left_knuckle_link">
    <inertial>
      <origin rpy="0 0 0" xyz="0.0004174 0.0081181 0.00092142"/>
      <mass value="0.00001"/>
      <inertia ixx="0.001" ixy="0.0" ixz="0.0" iyy="0.001" iyz="0.0" izz="0.001"/>
    </inertial>
    <visual>
      <origin rpy="0 0 0" xyz="0 0 0"/>
      <geometry>
        <mesh filename="package://le_arm/meshes/gripper/left_knuckle_link.STL"/>
      </geometry>
      <material name="">
        <color rgba="0.75294 0.75294 0.75294 1"/>
      </material>
    </visual>
    <collision>
      <origin rpy="0 0 0" xyz="0 0 0"/>
      <geometry>
        <mesh filename="package://le_arm/meshes/gripper/left_knuckle_link.STL"/>
      </geometry>
    </collision>
  </link>
  <gazebo reference="left_knuckle_link">
    <implicitSpringDamper>1</implicitSpringDamper>
    <mu1>100000</mu1>
    <mu2>100000</mu2>
    <kp>100000000.0</kp>
    <kd>1.0</kd>
  </gazebo>
  <joint name="left_knuckle_joint" type="revolute">
    <origin rpy="1.5708 -0.59692 1.5708" xyz="0.0045 -0.014 0.0325"/>
    <parent link="gripper_base_link"/>
    <child link="left_knuckle_link"/>
    <axis xyz="0 0 1"/>
    <limit effort="1000" lower="-1.57" upper="1.57" velocity="2.0"/>
  </joint>
  <link name="right_knuckle_link">
    <inertial>
      <origin rpy="0 0 0" xyz="0.00045059 0.0080041 0.0020288"/>
      <mass value="0.00001"/>
      <inertia ixx="0.001" ixy="0.0" ixz="0.0" iyy="0.001" iyz="0.0" izz="0.001"/>
    </inertial>
    <visual>
      <origin rpy="0 0 0" xyz="0 0 0"/>
      <geometry>
        <mesh filename="package://le_arm/meshes/gripper/right_knuckle_link.STL"/>
      </geometry>
      <material name="">
        <color rgba="0.75294 0.75294 0.75294 1"/>
      </material>
    </visual>
    <collision>
      <origin rpy="0 0 0" xyz="0 0 0"/>
      <geometry>
        <mesh filename="package://le_arm/meshes/gripper/right_knuckle_link.STL"/>
      </geometry>
    </collision>
  </link>
  <gazebo reference="right_knuckle_link">
    <implicitSpringDamper>1</implicitSpringDamper>
    <mu1>100000</mu1>
    <mu2>100000</mu2>
    <kp>100000000.0</kp>
    <kd>1.0</kd>
  </gazebo>
  <joint name="right_knuckle_joint" type="revolute">
    <origin rpy="1.5708 -0.69513 -1.5708" xyz="0.0075 0.014 0.0325"/>
    <parent link="gripper_base_link"/>
    <child link="right_knuckle_link"/>
    <axis xyz="0 0 -1"/>
    <limit effort="1000" lower="-1.57" upper="1.57" velocity="2.0"/>
    <mimic joint="left_knuckle_joint" multiplier="-1"/>
  </joint>
  <link name="left_inner_knuckle_link">
    <inertial>
      <origin rpy="0 0 0" xyz="-0.013801 1.3512E-10 -0.0091952"/>
      <mass value="0.00001"/>
      <inertia ixx="0.001" ixy="0.0" ixz="0.0" iyy="0.001" iyz="0.0" izz="0.001"/>
    </inertial>
    <visual>
      <origin rpy="0 0 0" xyz="0 0 0"/>
      <geometry>
        <mesh filename="package://le_arm/meshes/gripper/left_inner_knuckle_link.STL"/>
      </geometry>
      <material name="">
        <color rgba="0.75294 0.75294 0.75294 1"/>
      </material>
    </visual>
    <collision>
      <origin rpy="0 0 0" xyz="0 0 0"/>
      <geometry>
        <mesh filename="package://le_arm/meshes/gripper/left_inner_knuckle_link.STL"/>
      </geometry>
    </collision>
  </link>
  <gazebo reference="left_inner_knuckle_link">
    <implicitSpringDamper>1</implicitSpringDamper>
    <mu1>100000</mu1>
    <mu2>100000</mu2>
    <kp>100000000.0</kp>
    <kd>1.0</kd>
  </gazebo>
  <joint name="left_inner_knuckle_joint" type="revolute">
    <origin rpy="1.5708 0.97387 1.5708" xyz="0.0099 -0.005 0.051474"/>
    <parent link="gripper_base_link"/>
    <child link="left_inner_knuckle_link"/>
    <axis xyz="0 0 1"/>
    <limit effort="1000" lower="-1.57" upper="1.57" velocity="2.0"/>
    <mimic joint="left_knuckle_joint" multiplier="1"/>
  </joint>
  <link name="left_finger_link">
    <inertial>
      <origin rpy="0 0 0" xyz="-0.0038459 0.0027734 -5.6082E-05"/>
      <mass value="0.00001"/>
      <inertia ixx="0.001" ixy="0.0" ixz="0.0" iyy="0.001" iyz="0.0" izz="0.001"/>
    </inertial>
    <visual>
      <origin rpy="0 0 0" xyz="0 0 0"/>
      <geometry>
        <mesh filename="package://le_arm/meshes/gripper/left_finger_link.STL"/>
      </geometry>
      <material name="">
        <color rgba="0.75294 0.75294 0.75294 1"/>
      </material>
    </visual>
    <collision>
      <origin rpy="0 0 0" xyz="0 0 0"/>
      <geometry>
        <mesh filename="package://le_arm/meshes/gripper/left_finger_link.STL"/>
      </geometry>
    </collision>
  </link>
  <gazebo reference="left_finger_link">
    <implicitSpringDamper>1</implicitSpringDamper>
    <mu1>100000</mu1>
    <mu2>100000</mu2>
    <kp>100000000.0</kp>
    <kd>1.0</kd>
  </gazebo>
  <joint name="left_finger_joint" type="revolute">
    <origin rpy="9.0533E-10 -1.7902E-09 0.53096" xyz="-0.029 0 -0.0084"/>
    <parent link="left_inner_knuckle_link"/>
    <child link="left_finger_link"/>
    <axis xyz="0 0 1"/>
    <limit effort="1000" lower="-1.57" upper="1.57" velocity="2.0"/>
    <mimic joint="left_knuckle_joint" multiplier="-1"/>
  </joint>
  <link name="right_inner_knuckle_link">
    <inertial>
      <origin rpy="0 0 0" xyz="-0.013801 4.8285E-11 0.0069248"/>
      <mass value="0.00001"/>
      <inertia ixx="0.001" ixy="0.0" ixz="0.0" iyy="0.001" iyz="0.0" izz="0.001"/>
    </inertial>
    <visual>
      <origin rpy="0 0 0" xyz="0 0 0"/>
      <geometry>
        <mesh filename="package://le_arm/meshes/gripper/right_inner_knuckle_link.STL"/>
      </geometry>
      <material name="">
        <color rgba="0.75294 0.75294 0.75294 1"/>
      </material>
    </visual>
    <collision>
      <origin rpy="0 0 0" xyz="0 0 0"/>
      <geometry>
        <mesh filename="package://le_arm/meshes/gripper/right_inner_knuckle_link.STL"/>
      </geometry>
    </collision>
  </link>
  <gazebo reference="right_inner_knuckle_link">
    <implicitSpringDamper>1</implicitSpringDamper>
    <mu1>100000</mu1>
    <mu2>100000</mu2>
    <kp>100000000.0</kp>
    <kd>1.0</kd>
  </gazebo>
  <joint name="right_inner_knuckle_joint" type="revolute">
    <origin rpy="-1.5708 0.87566 -1.5708" xyz="-0.00622 0.005 0.051474"/>
    <parent link="gripper_base_link"/>
    <child link="right_inner_knuckle_link"/>
    <axis xyz="0 0 1"/>
    <limit effort="1000" lower="-1.57" upper="1.57" velocity="2.0"/>
    <mimic joint="left_knuckle_joint" multiplier="-1"/>
  </joint>
  <link name="right_finger_link">
    <inertial>
      <origin rpy="0 0 0" xyz="-0.0038459 0.0027734 0.0030561"/>
      <mass value="0.00001"/>
      <inertia ixx="0.001" ixy="0.0" ixz="0.0" iyy="0.001" iyz="0.0" izz="0.001"/>
    </inertial>
    <visual>
      <origin rpy="0 0 0" xyz="0 0 0"/>
      <geometry>
        <mesh filename="package://le_arm/meshes/gripper/right_finger_link.STL"/>
      </geometry>
      <material name="">
        <color rgba="0.75294 0.75294 0.75294 1"/>
      </material>
    </visual>
    <collision>
      <origin rpy="0 0 0" xyz="0 0 0"/>
      <geometry>
        <mesh filename="package://le_arm/meshes/gripper/right_finger_link.STL"/>
      </geometry>
    </collision>
  </link>
  <gazebo reference="right_finger_link">
    <implicitSpringDamper>1</implicitSpringDamper>
    <mu1>100000</mu1>
    <mu2>100000</mu2>
    <kp>100000000.0</kp>
    <kd>1.0</kd>
  </gazebo>
  <joint name="right_finger_joint" type="revolute">
    <origin rpy="-3.1416 1.7902E-09 -0.43275" xyz="-0.029 0 0.01072"/>
    <parent link="right_inner_knuckle_link"/>
    <child link="right_finger_link"/>
    <axis xyz="0 0 -1"/>
    <limit effort="1000" lower="-1.57" upper="1.57" velocity="2.0"/>
    <mimic joint="left_knuckle_joint" multiplier="1"/>
  </joint>
  <transmission name="wrist_2_transmission">
    <type>transmission_interface/SimpleTransmission</type>
    <joint name="wrist_2_joint">
      <hardwareInterface>hardware_interface/PositionJointInterface</hardwareInterface>
    </joint>
    <actuator name="wrist_2_motor">
      <mechanicalReduction>1</mechanicalReduction>
      <hardwareInterface>hardware_interface/PositionJointInterface</hardwareInterface>
    </actuator>
  </transmission>
  <transmission name="left_knuckle_joint_transmission">
    <type>transmission_interface/SimpleTransmission</type>
    <joint name="left_knuckle_joint">
      <hardwareInterface>hardware_interface/PositionJointInterface</hardwareInterface>
    </joint>
    <actuator name="left_knuckle_motor">
      <mechanicalReduction>1</mechanicalReduction>
      <hardwareInterface>hardware_interface/PositionJointInterface</hardwareInterface>
    </actuator>
  </transmission>
  <gazebo>
    <plugin filename="libroboticsgroup_gazebo_mimic_joint_plugin.so" name="MimicJointPlugin_right_finger">
      <joint>left_knuckle_joint</joint>
      <mimicJoint>right_finger_joint</mimicJoint>
    </plugin>
    <plugin filename="libroboticsgroup_gazebo_mimic_joint_plugin.so" name="MimicJointPlugin_right_inner_knuckle">
      <joint>left_knuckle_joint</joint>
      <mimicJoint>right_inner_knuckle_joint</mimicJoint>
      <multiplier>-1</multiplier>
      <offset>0.0</offset>
    </plugin>
    <plugin filename="libroboticsgroup_gazebo_mimic_joint_plugin.so" name="MimicJointPlugin_left_finger">
      <joint>left_knuckle_joint</joint>
      <mimicJoint>left_finger_joint</mimicJoint>
      <multiplier>-1</multiplier>
      <offset>0.0</offset>
    </plugin>
    <plugin filename="libroboticsgroup_gazebo_mimic_joint_plugin.so" name="MimicJointPlugin_left_inner_knuckle">
      <joint>left_knuckle_joint</joint>
      <mimicJoint>left_inner_knuckle_joint</mimicJoint>
    </plugin>
    <plugin filename="libroboticsgroup_gazebo_mimic_joint_plugin.so" name="Mimic_right_knuckle">
      <joint>left_knuckle_joint</joint>
      <mimicJoint>right_knuckle_joint</mimicJoint>
      <multiplier>-1</multiplier>
      <offset>0.0</offset>
    </plugin>
  </gazebo>
  <transmission name="shoulder_pan_trans">
    <type>transmission_interface/SimpleTransmission</type>
    <joint name="shoulder_pan_joint">
      <hardwareInterface>hardware_interface/PositionJointInterface</hardwareInterface>
    </joint>
    <actuator name="shoulder_pan_motor">
      <mechanicalReduction>1</mechanicalReduction>
      <hardwareInterface>hardware_interface/PositionJointInterface</hardwareInterface>
    </actuator>
  </transmission>
  <transmission name="shoulder_lift_trans">
    <type>transmission_interface/SimpleTransmission</type>
    <joint name="shoulder_lift_joint">
      <hardwareInterface>hardware_interface/PositionJointInterface</hardwareInterface>
    </joint>
    <actuator name="shoulder_lift_motor">
      <mechanicalReduction>1</mechanicalReduction>
      <hardwareInterface>hardware_interface/PositionJointInterface</hardwareInterface>
    </actuator>
  </transmission>
  <transmission name="elbow_trans">
    <type>transmission_interface/SimpleTransmission</type>
    <joint name="elbow_joint">
      <hardwareInterface>hardware_interface/PositionJointInterface</hardwareInterface>
    </joint>
    <actuator name="elbow_motor">
      <mechanicalReduction>1</mechanicalReduction>
      <hardwareInterface>hardware_interface/PositionJointInterface</hardwareInterface>
    </actuator>
  </transmission>
  <transmission name="wrist_1_trans">
    <type>transmission_interface/SimpleTransmission</type>
    <joint name="wrist_1_joint">
      <hardwareInterface>hardware_interface/PositionJointInterface</hardwareInterface>
    </joint>
    <actuator name="wrist_1_motor">
      <mechanicalReduction>1</mechanicalReduction>
      <hardwareInterface>hardware_interface/PositionJointInterface</hardwareInterface>
    </actuator>
  </transmission>
  <!-- Instantiate gps plugin. 
  <xacro:gps_plugin_macro
    namespace="${namespace}"
    gps_noise="true"
    >
  </xacro:gps_plugin_macro> -->
  <!-- Instantiate magnetometer plugin. 
  <xacro:magnetometer_plugin_macro
    namespace="${namespace}"
    pub_rate="20"
    noise_density="0.0004"
    random_walk="0.0000064"
    bias_correlation_time="600"
    mag_topic="/mag"
    >
  </xacro:magnetometer_plugin_macro> -->
  <!-- Instantiate barometer plugin. 
  <xacro:barometer_plugin_macro
    namespace="${namespace}"
    pub_rate="10"
    baro_topic="/baro"
    >
  </xacro:barometer_plugin_macro> -->
  <gazebo>
    <plugin filename="librotors_gazebo_mavlink_interface.so" name="mavlink_interface">
      <robotNamespace></robotNamespace>
      <mavlinkControlSubTopic>/mavlink/from</mavlinkControlSubTopic>
      <imuSubTopic>imu</imuSubTopic>
      <mavlinkHilSensorPubTopic>/mavlink/to</mavlinkHilSensorPubTopic>
      <motorSpeedsPubTopic>gazebo/command/motor_speed</motorSpeedsPubTopic>
      <gpsUpdateFreq>5.0</gpsUpdateFreq>
      <!-- Frequency of HIL GPS messages [Hz] -->
      <rotorCount>6</rotorCount>
      <!-- [Gauss] Below are the North, East, and Down components of the Earth's magnetic field at the reference location.
             The default reference location is Zurich (lat=+47.3667degN, lon=+8.5500degE, h=+500m, WGS84).
	     You can obtain the magnetic field strength for your location using the World Magnetic Model: 
             https://www.ngdc.noaa.gov/geomag/WMM/calculators.shtml -->
      <referenceMagNorth>0.21475</referenceMagNorth>
      <referenceMagEast>0.00797</referenceMagEast>
      <referenceMagDown>0.42817</referenceMagDown>
      <referenceLatitude>47.3667</referenceLatitude>
      <!-- the initial latitude [degrees [-90, 90]] -->
      <referenceLongitude>8.55</referenceLongitude>
      <!-- the initial longitude [degrees [-180, 180]] -->
      <referenceAltitude>500.0</referenceAltitude>
      <!-- the initial altitude [m] -->
    </plugin>
  </gazebo>
  <!-- IMU link -->
  <link name="/imu_link">
    <inertial>
      <inertia ixx="0.00001" ixy="0.0" ixz="0.0" iyy="0.00001" iyz="0.0" izz="0.00001"/>
      <mass value="0.015"/>
      <!-- [kg] -->
      <origin rpy="0 0 0" xyz="0 0 0"/>
    </inertial>
  </link>
  <!-- IMU joint -->
  <joint name="/imu_joint" type="revolute">
    <origin rpy="0 0 0" xyz="0 0 0"/>
    <parent link="base_link"/>
    <child link="/imu_link"/>
    <limit effort="0" lower="0" upper="0" velocity="0"/>
  </joint>
  <gazebo>
    <plugin filename="librotors_gazebo_imu_plugin.so" name="rotors_gazebo_imu_plugin">
      <!-- A good description of the IMU parameters can be found in the kalibr documentation:
           https://github.com/ethz-asl/kalibr/wiki/IMU-Noise-Model-and-Intrinsics -->
      <robotNamespace></robotNamespace>
      <!-- (string, required): ros namespace in which the messages are published -->
      <linkName>/imu_link</linkName>
      <!-- (string, required): name of the body which holds the IMU sensor -->
      <imuTopic>imu</imuTopic>
      <!-- (string): name of the sensor output topic and prefix of service names (defaults to imu) -->
      <gyroscopeNoiseDensity>0.0003394</gyroscopeNoiseDensity>
      <!-- Gyroscope noise density (two-sided spectrum) [rad/s/sqrt(Hz)] -->
      <gyroscopeRandomWalk>3.8785e-05</gyroscopeRandomWalk>
      <!-- Gyroscope bias random walk [rad/s/s/sqrt(Hz)] -->
      <gyroscopeBiasCorrelationTime>1000.0</gyroscopeBiasCorrelationTime>
      <!-- Gyroscope bias correlation time constant [s] -->
      <gyroscopeTurnOnBiasSigma>0.0087</gyroscopeTurnOnBiasSigma>
      <!-- Gyroscope turn on bias standard deviation [rad/s] -->
      <accelerometerNoiseDensity>0.004</accelerometerNoiseDensity>
      <!-- Accelerometer noise density (two-sided spectrum) [m/s^2/sqrt(Hz)] -->
      <accelerometerRandomWalk>0.006</accelerometerRandomWalk>
      <!-- Accelerometer bias random walk. [m/s^2/s/sqrt(Hz)] -->
      <accelerometerBiasCorrelationTime>300.0</accelerometerBiasCorrelationTime>
      <!-- Accelerometer bias correlation time constant [s] -->
      <accelerometerTurnOnBiasSigma>0.196</accelerometerTurnOnBiasSigma>
      <!-- Accelerometer turn on bias standard deviation [m/s^2] -->
    </plugin>
  </gazebo>
  <!-- Instantiate a VI sensor. -->
  <!-- <xacro:vi_sensor_macro namespace="$(arg name)" parent_link="base_link">
  <origin xyz="0.2 0.0 0.0" rpy="0.0 0.0 0.0" />
  </xacro:vi_sensor_macro> 

  <xacro:include filename="$(find le_arm)/urdf/sensors/camera.urdf.xacro"/> -->
</robot>

