<?xml version="1.0"?>
<robot xmlns:xacro="http://ros.org/wiki/xacro">
    <!-- <xacro:include filename="$(find reed_gazebo)/urdf/fall_cat.transmission.xacro" /> -->
     <xacro:property name="dL" value="0.05" />
        <link
            name="y_base_link">
            <inertial>
            <origin
                xyz="0.0 0 -0.00"
                rpy="0 0 0" />
            <mass value="0.00001" />
            <inertia ixx="0.001" ixy="0.0" ixz="0.0" iyy="0.001" iyz="0.0" izz="0.001" />
            </inertial>
            <visual>
            <origin
                xyz="0.0 0 -0.00"
                rpy="0 0 0" />
            <geometry>
                <mesh
                filename="package://le_arm/meshes/fall_cat/base.STL" />
            </geometry>
            <material
                name="">
                <color
                rgba="0.75294 0.75294 0.75294 1" />
            </material>
            </visual>
            <collision>
            <origin
                xyz="0 0 -0.00"
                rpy="0 0 0" />
            <geometry>
                <mesh
                filename="package://le_arm/meshes/fall_cat/base.STL" />
            </geometry>
            </collision>
        </link>

        <gazebo reference="y_base_link">
            <implicitSpringDamper>1</implicitSpringDamper>
            <mu1>100000</mu1>
            <mu2>100000</mu2>
            <kp>100000000.0</kp>
            <kd>1.0</kd>
        </gazebo> 

        <link
            name="y_link0">
            <inertial>
            <origin
                xyz="-0 -0 -0.0"
                rpy="0 0 0" />
            <mass value="0.01" />
            <inertia ixx="0.001" ixy="0.0" ixz="0.0" iyy="0.001" iyz="0.0" izz="0.001" />
            </inertial>
            <visual>
            <origin
                xyz="0 0 0"
                rpy="0 0 0" />
            <geometry>
                <mesh
                filename="package://le_arm/meshes/fall_cat/link11.STL" />
            </geometry>
            <material
                name="">
                <color
                rgba="0.75294 0.75294 0.75294 1" />
            </material>
            </visual>
            <collision>
            <origin
                xyz="0 0 0"
                rpy="0 0 0" />
            <geometry>
                <mesh
                filename="package://le_arm/meshes/fall_cat/link11.STL" />
            </geometry>
            </collision>
        </link>

                
        <gazebo reference="y_link0">
            <implicitSpringDamper>1</implicitSpringDamper>
            <mu1>100000</mu1>
            <mu2>100000</mu2>
            <kp>100000000.0</kp>
            <kd>1.0</kd>
        </gazebo> 

        <joint
            name="joint_y_base20"
            type="revolute">
            <origin
            xyz="0 0 0"
            rpy="0 0 0" />
            <parent
            link="y_base_link" />
            <child
            link="y_link0" />
            <axis
            xyz="0 1 0" />
            <limit
            lower="-1.57"
            upper="0"
            effort="1000"
            velocity="2" />
        </joint>
        <link
            name="link1">
            <inertial>
            <origin
                xyz="0 0 0"
                rpy="0 0 0" />
            <mass value="0.00001" />
            <inertia ixx="0.001" ixy="0.0" ixz="0.0" iyy="0.001" iyz="0.0" izz="0.001" />
            </inertial>
            <visual>
            <origin
                xyz="0 0 0"
                rpy="0 0 0" />
            <geometry>
                <mesh
                filename="package://le_arm/meshes/fall_cat/link21.STL" />
            </geometry>
            <material
                name="">
                <color
                rgba="0.75294 0.75294 0.75294 1" />
            </material>
            </visual>
            <collision>
            <origin
                xyz="0 0 0"
                rpy="0 0 0" />
            <geometry>
                <mesh
                filename="package://le_arm/meshes/fall_cat/link21.STL" />
            </geometry>
            </collision>
        </link>

        <gazebo reference="link1">
            <implicitSpringDamper>1</implicitSpringDamper>
            <mu1>100000</mu1>
            <mu2>100000</mu2>
            <kp>100000000.0</kp>
            <kd>1.0</kd>
        </gazebo> 

        <joint
            name="joint_021y" 
            type="revolute">
            <origin
            xyz="0.15 0 0"
            rpy="0 0 0" />
            <parent
            link="y_link0" />
            <child
            link="link1" />
            <axis
            xyz="0 1 0" />
            <limit
            lower="-1.57"
            upper="1.57"
            effort="1000"
            velocity="2" />
        </joint>
        
         <link
            name="x_link0">
            <inertial>
            <origin
                xyz="0 0 0"
                rpy="0 1.57 0" />
            <mass value="0.00001" />
            <inertia ixx="0.001" ixy="0.0" ixz="0.0" iyy="0.001" iyz="0.0" izz="0.001" />
            </inertial>
            <visual>
            <origin
                xyz="0 0 0"
               rpy="0 1.57 0" />
            <geometry>
                <mesh
                filename="package://le_arm/meshes/fall_cat/link11.STL" />
            </geometry>
            <material
                name="">
                <color
                rgba="0.75294 0.75294 0.75294 1" />
            </material>
            </visual>
            <collision>
            <origin
                xyz="0 0 0"
                rpy="0 1.57 0" />
            <geometry>
                <mesh
                filename="package://le_arm/meshes/fall_cat/link11.STL" />
            </geometry>
            </collision>
        </link>

        <gazebo reference="x_link0">
            <implicitSpringDamper>1</implicitSpringDamper>
            <mu1>100000</mu1>
            <mu2>100000</mu2>
            <kp>100000000.0</kp>
            <kd>1.0</kd>
        </gazebo> 


        <joint
            name="joint_120y" 
            type="revolute">
            <origin
            xyz="0.15 0 0"
            rpy="0 1.57 0" />
            <parent
            link="link1" />
            <child
            link="x_link0" />
            <axis
            xyz="0 1 0" />
            <limit
            lower="-1.57"
            upper="1.57"
            effort="1000"
            velocity="2" />
        </joint>
        
      <link
            name="x_base_link">
            <inertial>
            <origin
                xyz="0 0 0"
                rpy="0 0 0" />
            <mass value="0.00001" />
            <inertia ixx="0.001" ixy="0.0" ixz="0.0" iyy="0.001" iyz="0.0" izz="0.001" />
            </inertial>
            <visual>
            <origin
                xyz="0 0 0"
                rpy="0 0 0" />
            <geometry>
                <mesh
                filename="package://le_arm/meshes/fall_cat/base.STL" />
            </geometry>
            <material
                name="">
                <color
                rgba="0.75294 0.75294 0.75294 1" />
            </material>
            </visual>
            <collision>
            <origin
                xyz="0 0 0"
                rpy="0 0 0" />
            <geometry>
                <mesh
                filename="package://le_arm/meshes/fall_cat/base.STL" />
            </geometry>
            </collision>
        </link>

        <gazebo reference="x_base_link">
            <implicitSpringDamper>1</implicitSpringDamper>
            <mu1>100000</mu1>
            <mu2>100000</mu2>
            <kp>100000000.0</kp>
            <kd>1.0</kd>
        </gazebo> 


        <joint
            name="joint_02basey" 
            type="revolute">
            <origin
            xyz="0.15 0 0"
            rpy="0 1.57 0" />
            <parent
            link="link1" />
            <child
            link="x_link0" />
            <axis
            xyz="0 1 0" />
            <limit
            lower="-1.57"
            upper="1.57"
            effort="1000"
            velocity="2" />
        </joint>

        <!-- <xacro:le_arm_gripper prefix="" parent="wrist_1_link" >
            <origin xyz="0 0.009 0.059" rpy="0 0 0"/>
        </xacro:le_arm_gripper> -->


        <!-- <xacro:le_arm_transmission prefix=""/> -->

</robot>