<?xml version="1.0"?>
<robot xmlns:xacro="http://ros.org/wiki/xacro">
    <xacro:include filename="$(find reed_gazebo)/urdf/le_arm.transmission.xacro" />
    <xacro:include filename="$(find le_arm)/urdf/le_arm_gripper.urdf.xacro" />
    <xacro:macro name="le_arm" params="parent *origin">  
        <joint name="arm_base_joint" type="fixed">
            <parent link="${parent}"/>
            <child link="arm_base_link"/>
            <xacro:insert_block name="origin"/>
        </joint>

        <link
            name="arm_base_link">
            <inertial>
            <origin
                xyz="0.0 0 -0.00"
                rpy="0 0 0" />
            <mass value="0.00001" />
            <inertia ixx="0.001" ixy="0.0" ixz="0.0" iyy="0.001" iyz="0.0" izz="0.001" />
            </inertial>
            <visual>
            <origin
                xyz="0.0 0 -0.00"
                rpy="0 0 0" />
            <geometry>
                <mesh
                filename="package://le_arm/meshes/arm/base1.STL" />
            </geometry>
            <material
                name="">
                <color
                rgba="0.75294 0.75294 0.75294 1" />
            </material>
            </visual>
            <collision>
            <origin
                xyz="0 0 -0.00"
                rpy="0 0 0" />
            <geometry>
                <mesh
                filename="package://le_arm/meshes/arm/base1.STL" />
            </geometry>
            </collision>
        </link>

        <gazebo reference="arm_base_link">
            <implicitSpringDamper>1</implicitSpringDamper>
            <mu1>100000</mu1>
            <mu2>100000</mu2>
            <kp>100000000.0</kp>
            <kd>1.0</kd>
        </gazebo> 

        <link
            name="shoulder_link">
            <inertial>
            <origin
                xyz="-0 -0 -0.0"
                rpy="0 0 0" />
            <mass value="0.01" />
            <inertia ixx="0.001" ixy="0.0" ixz="0.0" iyy="0.001" iyz="0.0" izz="0.001" />
            </inertial>
            <visual>
            <origin
                xyz="0 0 0"
                rpy="0 0 0" />
            <geometry>
                <mesh
                filename="package://le_arm/meshes/arm/link11.STL" />
            </geometry>
            <material
                name="">
                <color
                rgba="0.75294 0.75294 0.75294 1" />
            </material>
            </visual>
            <collision>
            <origin
                xyz="0 0 0"
                rpy="0 0 0" />
            <geometry>
                <mesh
                filename="package://le_arm/meshes/arm/link11.STL" />
            </geometry>
            </collision>
        </link>

                
        <gazebo reference="shoulder_link">
            <implicitSpringDamper>1</implicitSpringDamper>
            <mu1>100000</mu1>
            <mu2>100000</mu2>
            <kp>100000000.0</kp>
            <kd>1.0</kd>
        </gazebo> 

        <joint
            name="shoulder_pan_joint"
            type="revolute">
            <origin
            xyz="0 0 0"
            rpy="0 0 0" />
            <parent
            link="arm_base_link" />
            <child
            link="shoulder_link" />
            <axis
            xyz="0 1 0" />
            <limit
            lower="0"
            upper="3.14"
            effort="1000"
            velocity="2" />
        </joint>
        <link
            name="upper_arm_link">
            <inertial>
            <origin
                xyz="0 0 0"
                rpy="0 0 0" />
            <mass value="0.00001" />
            <inertia ixx="0.001" ixy="0.0" ixz="0.0" iyy="0.001" iyz="0.0" izz="0.001" />
            </inertial>
            <visual>
            <origin
                xyz="0 0 0"
                rpy="0 0 0" />
            <geometry>
                <mesh
                filename="package://le_arm/meshes/arm/link21.STL" />
            </geometry>
            <material
                name="">
                <color
                rgba="0.75294 0.75294 0.75294 1" />
            </material>
            </visual>
            <collision>
            <origin
                xyz="0 0 0"
                rpy="0 0 0" />
            <geometry>
                <mesh
                filename="package://le_arm/meshes/arm/link21.STL" />
            </geometry>
            </collision>
        </link>

        <gazebo reference="upper_arm_link">
            <implicitSpringDamper>1</implicitSpringDamper>
            <mu1>100000</mu1>
            <mu2>100000</mu2>
            <kp>100000000.0</kp>
            <kd>1.0</kd>
        </gazebo> 

        <joint
            name="shoulder_lift_joint" 
            type="revolute">
            <origin
            xyz="0.15 0 0"
            rpy="0 0 0" />
            <parent
            link="shoulder_link" />
            <child
            link="upper_arm_link" />
            <axis
            xyz="0 1 0" />
            <limit
            lower="-1.57"
            upper="1.57"
            effort="1000"
            velocity="2" />
        </joint>
        


        <!-- <xacro:le_arm_gripper prefix="" parent="wrist_1_link" >
            <origin xyz="0 0.009 0.059" rpy="0 0 0"/>
        </xacro:le_arm_gripper> -->


        <xacro:le_arm_transmission prefix=""/>

    </xacro:macro>    
</robot>