<?xml version="1.0" encoding="utf-8"?>
<!-- =================================================================================== -->
<!-- |    This document was autogenerated by xacro from tilt_hex.xacro                 | -->
<!-- |    EDITING THIS FILE BY HAND IS NOT RECOMMENDED                                 | -->
<!-- =================================================================================== -->
<robot name="reed_quad_x">
  <!-- Included URDF Files -->
  <link name="tilt_hex/base_link"/>
  <joint name="tilt_hex/base_joint" type="fixed">
    <origin rpy="0 0 0" xyz="0 0 0"/>
    <parent link="tilt_hex/base_link"/>
    <child link="tilt_hex/base_link_inertia"/>
  </joint>
  <link name="tilt_hex/base_link_inertia">
    <inertial>
      <mass value="1.5"/>
      <!-- [kg] -->
      <origin rpy="0 0 0" xyz="0 0 0"/>
      <inertia ixx="0.0347563" ixy="0.0" ixz="0.0" iyy="0.0458929" iyz="0.0" izz="0.0977"/>
    </inertial>
    <visual>
      <origin rpy="0 0 0" xyz="0 0 0"/>
      <geometry>
        <mesh filename="package://reed_gazebo/meshes/reed_quad_x/body-hex.STL" scale="1 1 1"/>
      </geometry>
    </visual>
    <collision>
      <origin rpy="0 0 0" xyz="0 0 0"/>
      <geometry>
        <box size="0.47 0.47 0.11"/>
        <!-- [m] [m] [m] -->
      </geometry>
    </collision>
  </link>
  <!-- attach multirotor_base_plugin to the base_link -->
  <gazebo>
    <plugin filename="librotors_gazebo_multirotor_base_plugin.so" name="multirotor_base_plugin">
      <robotNamespace>tilt_hex</robotNamespace>
      <linkName>tilt_hex/base_link</linkName>
      <rotorVelocitySlowdownSim>10</rotorVelocitySlowdownSim>
    </plugin>
  </gazebo>
  <!-- Rotor tilt_unit -->
  <joint name="tilt_hex/tilt_unit_0_revolutejoint" type="continuous">
    <origin rpy="0 0 -0.523333" xyz="0.09 -0.05196 0.135"/>
    <axis xyz="1 0 0"/>
    <parent link="tilt_hex/base_link"/>
    <child link="tilt_hex/tilt_unit_0"/>
  </joint>
  <link name="tilt_hex/tilt_unit_0">
    <inertial>
      <mass value="0.2"/>
      <!-- [kg] -->
      <inertia ixx="0.00034257" ixy="0" ixz="0" iyy="0.0013205" iyz="0" izz="0.0010037"/>
      <!-- [kg m^2] [kg m^2] [kg m^2] [kg m^2] [kg m^2] [kg m^2] -->
    </inertial>
    <visual>
      <geometry>
        <mesh filename="package://reed_gazebo/meshes/reed_quad_x/rotortilt.STL" scale="1 1 1"/>
      </geometry>
    </visual>
    <collision>
      <geometry>
        <box size="0.005 0.005 0.005"/>
        <!-- [m] -->
      </geometry>
    </collision>
  </link>
  <gazebo>
    <plugin filename="librotors_gazebo_motor_model.so" name="one_tilt_unit_model">
      <robotNamespace>tilt_hex</robotNamespace>
      <jointName>tilt_hex/tilt_unit_0_revolutejoint</jointName>
      <linkName>tilt_hex/tilt_unit_0</linkName>
      <turningDirection>ccw</turningDirection>
      <motorType>position</motorType>
      <commandSubTopic>/gazebo/command/motor_speed</commandSubTopic>
      <motorNumber>12</motorNumber>
      <motorSpeedPubTopic>/tilt_motor_0/velocity</motorSpeedPubTopic>
      <motorPositionPubTopic>/tilt_motor_0/position</motorPositionPubTopic>
      <joint_control_pid>
        <p>1.0</p>
        <i>0.0</i>
        <d>0.01</d>
        <iMax>1.0</iMax>
        <iMin>-1.0</iMin>
        <cmdMax>2.0</cmdMax>
        <cmdMin>-2.0</cmdMin>
      </joint_control_pid>
    </plugin>
  </gazebo>
  <gazebo reference="tilt_hex/tilt_unit_0">
    <material>Gazebo/White</material>
  </gazebo>
  <!-- Rotor -->
  <joint name="rotor_0_joint" type="continuous">
    <origin rpy="0 0 0" xyz="0.22 0 0.04"/>
    <axis xyz="0 0 1"/>
    <parent link="tilt_hex/tilt_unit_0"/>
    <child link="rotor_0"/>
  </joint>
  <link name="rotor_0">
    <inertial>
      <mass value="0.005"/>
      <!-- [kg] -->
      <inertia ixx="9.7499961e-07" ixy="0.0" ixz="0.0" iyy="4.1704149985e-05" iyz="0.0" izz="4.2604149625e-05"/>
    </inertial>
    <visual>
      <geometry>
        <mesh filename="package://rotors_description/meshes/propeller_ccw.dae" scale="0.1 0.1 0.1"/>
      </geometry>
    </visual>
    <collision>
      <geometry>
        <cylinder length="0.005" radius="0.1"/>
        <!-- [m] -->
      </geometry>
    </collision>
  </link>
  <gazebo>
    <plugin filename="librotors_gazebo_motor_model.so" name="one_motor_model">
      <robotNamespace>tilt_hex</robotNamespace>
      <jointName>rotor_0_joint</jointName>
      <linkName>rotor_0</linkName>
      <turningDirection>ccw</turningDirection>
      <timeConstantUp>0.0125</timeConstantUp>
      <timeConstantDown>0.025</timeConstantDown>
      <maxRotVelocity>838</maxRotVelocity>
      <motorConstant>8.54858e-06</motorConstant>
      <momentConstant>0.016</momentConstant>
      <commandSubTopic>/gazebo/command/motor_speed</commandSubTopic>
      <motorNumber>0</motorNumber>
      <rotorDragCoefficient>8.06428e-05</rotorDragCoefficient>
      <rollingMomentCoefficient>1e-06</rollingMomentCoefficient>
      <motorSpeedPubTopic>/motor_speed/0</motorSpeedPubTopic>
      <rotorVelocitySlowdownSim>10</rotorVelocitySlowdownSim>
    </plugin>
  </gazebo>
  <gazebo reference="rotor_0">
    <material>Gazebo/Blue</material>
  </gazebo>
  <!-- Rotor tilt_unit -->
  <joint name="tilt_hex/tilt_unit_1_revolutejoint" type="continuous">
    <origin rpy="0 0 -1.569999" xyz="0 -0.10392 0.135"/>
    <axis xyz="1 0 0"/>
    <parent link="tilt_hex/base_link"/>
    <child link="tilt_hex/tilt_unit_1"/>
  </joint>
  <link name="tilt_hex/tilt_unit_1">
    <inertial>
      <mass value="0.2"/>
      <!-- [kg] -->
      <inertia ixx="0.00034257" ixy="0" ixz="0" iyy="0.0013205" iyz="0" izz="0.0010037"/>
      <!-- [kg m^2] [kg m^2] [kg m^2] [kg m^2] [kg m^2] [kg m^2] -->
    </inertial>
    <visual>
      <geometry>
        <mesh filename="package://reed_gazebo/meshes/reed_quad_x/rotortilt.STL" scale="1 1 1"/>
      </geometry>
    </visual>
    <collision>
      <geometry>
        <box size="0.005 0.005 0.005"/>
        <!-- [m] -->
      </geometry>
    </collision>
  </link>
  <gazebo>
    <plugin filename="librotors_gazebo_motor_model.so" name="two_tilt_unit_model">
      <robotNamespace>tilt_hex</robotNamespace>
      <jointName>tilt_hex/tilt_unit_1_revolutejoint</jointName>
      <linkName>tilt_hex/tilt_unit_1</linkName>
      <turningDirection>ccw</turningDirection>
      <motorType>position</motorType>
      <commandSubTopic>/gazebo/command/motor_speed</commandSubTopic>
      <motorNumber>13</motorNumber>
      <motorSpeedPubTopic>/tilt_motor_1/velocity</motorSpeedPubTopic>
      <motorPositionPubTopic>/tilt_motor_1/position</motorPositionPubTopic>
      <joint_control_pid>
        <p>1.0</p>
        <i>0.0</i>
        <d>0.01</d>
        <iMax>1.0</iMax>
        <iMin>-1.0</iMin>
        <cmdMax>2.0</cmdMax>
        <cmdMin>-2.0</cmdMin>
      </joint_control_pid>
    </plugin>
  </gazebo>
  <gazebo reference="tilt_hex/tilt_unit_1">
    <material>Gazebo/White</material>
  </gazebo>
  <!-- Rotor -->
  <joint name="rotor_1_joint" type="continuous">
    <origin rpy="0 0 0" xyz="0.22 0 0.04"/>
    <axis xyz="0 0 1"/>
    <parent link="tilt_hex/tilt_unit_1"/>
    <child link="rotor_1"/>
  </joint>
  <link name="rotor_1">
    <inertial>
      <mass value="0.005"/>
      <!-- [kg] -->
      <inertia ixx="9.7499961e-07" ixy="0.0" ixz="0.0" iyy="4.1704149985e-05" iyz="0.0" izz="4.2604149625e-05"/>
    </inertial>
    <visual>
      <geometry>
        <mesh filename="package://rotors_description/meshes/propeller_cw.dae" scale="0.1 0.1 0.1"/>
      </geometry>
    </visual>
    <collision>
      <geometry>
        <cylinder length="0.005" radius="0.1"/>
        <!-- [m] -->
      </geometry>
    </collision>
  </link>
  <gazebo>
    <plugin filename="librotors_gazebo_motor_model.so" name="two_motor_model">
      <robotNamespace>tilt_hex</robotNamespace>
      <jointName>rotor_1_joint</jointName>
      <linkName>rotor_1</linkName>
      <turningDirection>cw</turningDirection>
      <timeConstantUp>0.0125</timeConstantUp>
      <timeConstantDown>0.025</timeConstantDown>
      <maxRotVelocity>838</maxRotVelocity>
      <motorConstant>8.54858e-06</motorConstant>
      <momentConstant>0.016</momentConstant>
      <commandSubTopic>/gazebo/command/motor_speed</commandSubTopic>
      <motorNumber>1</motorNumber>
      <rotorDragCoefficient>8.06428e-05</rotorDragCoefficient>
      <rollingMomentCoefficient>1e-06</rollingMomentCoefficient>
      <motorSpeedPubTopic>/motor_speed/1</motorSpeedPubTopic>
      <rotorVelocitySlowdownSim>10</rotorVelocitySlowdownSim>
    </plugin>
  </gazebo>
  <gazebo reference="rotor_1">
    <material>Gazebo/Red</material>
  </gazebo>
  <!-- Rotor tilt_unit -->
  <joint name="tilt_hex/tilt_unit_2_revolutejoint" type="continuous">
    <origin rpy="0 0 -2.616665" xyz="-0.09 -0.05196 0.135"/>
    <axis xyz="1 0 0"/>
    <parent link="tilt_hex/base_link"/>
    <child link="tilt_hex/tilt_unit_2"/>
  </joint>
  <link name="tilt_hex/tilt_unit_2">
    <inertial>
      <mass value="0.2"/>
      <!-- [kg] -->
      <inertia ixx="0.00034257" ixy="0" ixz="0" iyy="0.0013205" iyz="0" izz="0.0010037"/>
      <!-- [kg m^2] [kg m^2] [kg m^2] [kg m^2] [kg m^2] [kg m^2] -->
    </inertial>
    <visual>
      <geometry>
        <mesh filename="package://reed_gazebo/meshes/reed_quad_x/rotortilt.STL" scale="1 1 1"/>
      </geometry>
    </visual>
    <collision>
      <geometry>
        <box size="0.005 0.005 0.005"/>
        <!-- [m] -->
      </geometry>
    </collision>
  </link>
  <gazebo>
    <plugin filename="librotors_gazebo_motor_model.so" name="three_tilt_unit_model">
      <robotNamespace>tilt_hex</robotNamespace>
      <jointName>tilt_hex/tilt_unit_2_revolutejoint</jointName>
      <linkName>tilt_hex/tilt_unit_2</linkName>
      <turningDirection>ccw</turningDirection>
      <motorType>position</motorType>
      <commandSubTopic>/gazebo/command/motor_speed</commandSubTopic>
      <motorNumber>14</motorNumber>
      <motorSpeedPubTopic>/tilt_motor_2/velocity</motorSpeedPubTopic>
      <motorPositionPubTopic>/tilt_motor_2/position</motorPositionPubTopic>
      <joint_control_pid>
        <p>1.0</p>
        <i>0.0</i>
        <d>0.01</d>
        <iMax>1.0</iMax>
        <iMin>-1.0</iMin>
        <cmdMax>2.0</cmdMax>
        <cmdMin>-2.0</cmdMin>
      </joint_control_pid>
    </plugin>
  </gazebo>
  <gazebo reference="tilt_hex/tilt_unit_2">
    <material>Gazebo/White</material>
  </gazebo>
  <!-- Rotor -->
  <joint name="rotor_2_joint" type="continuous">
    <origin rpy="0 0 0" xyz="0.22 0 0.04"/>
    <axis xyz="0 0 1"/>
    <parent link="tilt_hex/tilt_unit_2"/>
    <child link="rotor_2"/>
  </joint>
  <link name="rotor_2">
    <inertial>
      <mass value="0.005"/>
      <!-- [kg] -->
      <inertia ixx="9.7499961e-07" ixy="0.0" ixz="0.0" iyy="4.1704149985e-05" iyz="0.0" izz="4.2604149625e-05"/>
    </inertial>
    <visual>
      <geometry>
        <mesh filename="package://rotors_description/meshes/propeller_ccw.dae" scale="0.1 0.1 0.1"/>
      </geometry>
    </visual>
    <collision>
      <geometry>
        <cylinder length="0.005" radius="0.1"/>
        <!-- [m] -->
      </geometry>
    </collision>
  </link>
  <gazebo>
    <plugin filename="librotors_gazebo_motor_model.so" name="three_motor_model">
      <robotNamespace>tilt_hex</robotNamespace>
      <jointName>rotor_2_joint</jointName>
      <linkName>rotor_2</linkName>
      <turningDirection>ccw</turningDirection>
      <timeConstantUp>0.0125</timeConstantUp>
      <timeConstantDown>0.025</timeConstantDown>
      <maxRotVelocity>838</maxRotVelocity>
      <motorConstant>8.54858e-06</motorConstant>
      <momentConstant>0.016</momentConstant>
      <commandSubTopic>/gazebo/command/motor_speed</commandSubTopic>
      <motorNumber>2</motorNumber>
      <rotorDragCoefficient>8.06428e-05</rotorDragCoefficient>
      <rollingMomentCoefficient>1e-06</rollingMomentCoefficient>
      <motorSpeedPubTopic>/motor_speed/2</motorSpeedPubTopic>
      <rotorVelocitySlowdownSim>10</rotorVelocitySlowdownSim>
    </plugin>
  </gazebo>
  <gazebo reference="rotor_2">
    <material>Gazebo/Blue</material>
  </gazebo>
  <!-- Rotor tilt_unit -->
  <joint name="tilt_hex/tilt_unit_3_revolutejoint" type="continuous">
    <origin rpy="0 0 -3.663331" xyz="-0.09 0.05196 0.135"/>
    <axis xyz="1 0 0"/>
    <parent link="tilt_hex/base_link"/>
    <child link="tilt_hex/tilt_unit_3"/>
  </joint>
  <link name="tilt_hex/tilt_unit_3">
    <inertial>
      <mass value="0.2"/>
      <!-- [kg] -->
      <inertia ixx="0.00034257" ixy="0" ixz="0" iyy="0.0013205" iyz="0" izz="0.0010037"/>
      <!-- [kg m^2] [kg m^2] [kg m^2] [kg m^2] [kg m^2] [kg m^2] -->
    </inertial>
    <visual>
      <geometry>
        <mesh filename="package://reed_gazebo/meshes/reed_quad_x/rotortilt.STL" scale="1 1 1"/>
      </geometry>
    </visual>
    <collision>
      <geometry>
        <box size="0.005 0.005 0.005"/>
        <!-- [m] -->
      </geometry>
    </collision>
  </link>
  <gazebo>
    <plugin filename="librotors_gazebo_motor_model.so" name="four_tilt_unit_model">
      <robotNamespace>tilt_hex</robotNamespace>
      <jointName>tilt_hex/tilt_unit_3_revolutejoint</jointName>
      <linkName>tilt_hex/tilt_unit_3</linkName>
      <turningDirection>ccw</turningDirection>
      <motorType>position</motorType>
      <commandSubTopic>/gazebo/command/motor_speed</commandSubTopic>
      <motorNumber>15</motorNumber>
      <motorSpeedPubTopic>/tilt_motor_3/velocity</motorSpeedPubTopic>
      <motorPositionPubTopic>/tilt_motor_3/position</motorPositionPubTopic>
      <joint_control_pid>
        <p>1.0</p>
        <i>0.0</i>
        <d>0.01</d>
        <iMax>1.0</iMax>
        <iMin>-1.0</iMin>
        <cmdMax>2.0</cmdMax>
        <cmdMin>-2.0</cmdMin>
      </joint_control_pid>
    </plugin>
  </gazebo>
  <gazebo reference="tilt_hex/tilt_unit_3">
    <material>Gazebo/White</material>
  </gazebo>
  <!-- Rotor -->
  <joint name="rotor_3_joint" type="continuous">
    <origin rpy="0 0 0" xyz="0.22 0 0.04"/>
    <axis xyz="0 0 1"/>
    <parent link="tilt_hex/tilt_unit_3"/>
    <child link="rotor_3"/>
  </joint>
  <link name="rotor_3">
    <inertial>
      <mass value="0.005"/>
      <!-- [kg] -->
      <inertia ixx="9.7499961e-07" ixy="0.0" ixz="0.0" iyy="4.1704149985e-05" iyz="0.0" izz="4.2604149625e-05"/>
    </inertial>
    <visual>
      <geometry>
        <mesh filename="package://rotors_description/meshes/propeller_cw.dae" scale="0.1 0.1 0.1"/>
      </geometry>
    </visual>
    <collision>
      <geometry>
        <cylinder length="0.005" radius="0.1"/>
        <!-- [m] -->
      </geometry>
    </collision>
  </link>
  <gazebo>
    <plugin filename="librotors_gazebo_motor_model.so" name="four_motor_model">
      <robotNamespace>tilt_hex</robotNamespace>
      <jointName>rotor_3_joint</jointName>
      <linkName>rotor_3</linkName>
      <turningDirection>cw</turningDirection>
      <timeConstantUp>0.0125</timeConstantUp>
      <timeConstantDown>0.025</timeConstantDown>
      <maxRotVelocity>838</maxRotVelocity>
      <motorConstant>8.54858e-06</motorConstant>
      <momentConstant>0.016</momentConstant>
      <commandSubTopic>/gazebo/command/motor_speed</commandSubTopic>
      <motorNumber>3</motorNumber>
      <rotorDragCoefficient>8.06428e-05</rotorDragCoefficient>
      <rollingMomentCoefficient>1e-06</rollingMomentCoefficient>
      <motorSpeedPubTopic>/motor_speed/3</motorSpeedPubTopic>
      <rotorVelocitySlowdownSim>10</rotorVelocitySlowdownSim>
    </plugin>
  </gazebo>
  <gazebo reference="rotor_3">
    <material>Gazebo/Red</material>
  </gazebo>
  <!-- Rotor tilt_unit -->
  <joint name="tilt_hex/tilt_unit_4_revolutejoint" type="continuous">
    <origin rpy="0 0 -4.709991" xyz="0 0.10392 0.135"/>
    <axis xyz="1 0 0"/>
    <parent link="tilt_hex/base_link"/>
    <child link="tilt_hex/tilt_unit_4"/>
  </joint>
  <link name="tilt_hex/tilt_unit_4">
    <inertial>
      <mass value="0.2"/>
      <!-- [kg] -->
      <inertia ixx="0.00034257" ixy="0" ixz="0" iyy="0.0013205" iyz="0" izz="0.0010037"/>
      <!-- [kg m^2] [kg m^2] [kg m^2] [kg m^2] [kg m^2] [kg m^2] -->
    </inertial>
    <visual>
      <geometry>
        <mesh filename="package://reed_gazebo/meshes/reed_quad_x/rotortilt.STL" scale="1 1 1"/>
      </geometry>
    </visual>
    <collision>
      <geometry>
        <box size="0.005 0.005 0.005"/>
        <!-- [m] -->
      </geometry>
    </collision>
  </link>
  <gazebo>
    <plugin filename="librotors_gazebo_motor_model.so" name="five_tilt_unit_model">
      <robotNamespace>tilt_hex</robotNamespace>
      <jointName>tilt_hex/tilt_unit_4_revolutejoint</jointName>
      <linkName>tilt_hex/tilt_unit_4</linkName>
      <turningDirection>ccw</turningDirection>
      <motorType>position</motorType>
      <commandSubTopic>/gazebo/command/motor_speed</commandSubTopic>
      <motorNumber>16</motorNumber>
      <motorSpeedPubTopic>/tilt_motor_4/velocity</motorSpeedPubTopic>
      <motorPositionPubTopic>/tilt_motor_4/position</motorPositionPubTopic>
      <joint_control_pid>
        <p>1.0</p>
        <i>0.0</i>
        <d>0.01</d>
        <iMax>1.0</iMax>
        <iMin>-1.0</iMin>
        <cmdMax>2.0</cmdMax>
        <cmdMin>-2.0</cmdMin>
      </joint_control_pid>
    </plugin>
  </gazebo>
  <gazebo reference="tilt_hex/tilt_unit_4">
    <material>Gazebo/White</material>
  </gazebo>
  <!-- Rotor -->
  <joint name="rotor_4_joint" type="continuous">
    <origin rpy="0 0 0" xyz="0.22 0 0.04"/>
    <axis xyz="0 0 1"/>
    <parent link="tilt_hex/tilt_unit_4"/>
    <child link="rotor_4"/>
  </joint>
  <link name="rotor_4">
    <inertial>
      <mass value="0.005"/>
      <!-- [kg] -->
      <inertia ixx="9.7499961e-07" ixy="0.0" ixz="0.0" iyy="4.1704149985e-05" iyz="0.0" izz="4.2604149625e-05"/>
    </inertial>
    <visual>
      <geometry>
        <mesh filename="package://rotors_description/meshes/propeller_ccw.dae" scale="0.1 0.1 0.1"/>
      </geometry>
    </visual>
    <collision>
      <geometry>
        <cylinder length="0.005" radius="0.1"/>
        <!-- [m] -->
      </geometry>
    </collision>
  </link>
  <gazebo>
    <plugin filename="librotors_gazebo_motor_model.so" name="five_motor_model">
      <robotNamespace>tilt_hex</robotNamespace>
      <jointName>rotor_4_joint</jointName>
      <linkName>rotor_4</linkName>
      <turningDirection>ccw</turningDirection>
      <timeConstantUp>0.0125</timeConstantUp>
      <timeConstantDown>0.025</timeConstantDown>
      <maxRotVelocity>838</maxRotVelocity>
      <motorConstant>8.54858e-06</motorConstant>
      <momentConstant>0.016</momentConstant>
      <commandSubTopic>/gazebo/command/motor_speed</commandSubTopic>
      <motorNumber>4</motorNumber>
      <rotorDragCoefficient>8.06428e-05</rotorDragCoefficient>
      <rollingMomentCoefficient>1e-06</rollingMomentCoefficient>
      <motorSpeedPubTopic>/motor_speed/4</motorSpeedPubTopic>
      <rotorVelocitySlowdownSim>10</rotorVelocitySlowdownSim>
    </plugin>
  </gazebo>
  <gazebo reference="rotor_4">
    <material>Gazebo/Blue</material>
  </gazebo>
  <!-- Rotor tilt_unit -->
  <joint name="tilt_hex/tilt_unit_5_revolutejoint" type="continuous">
    <origin rpy="0 0 -5.75663" xyz="0.09 0.05196 0.135"/>
    <axis xyz="1 0 0"/>
    <parent link="tilt_hex/base_link"/>
    <child link="tilt_hex/tilt_unit_5"/>
  </joint>
  <link name="tilt_hex/tilt_unit_5">
    <inertial>
      <mass value="0.2"/>
      <!-- [kg] -->
      <inertia ixx="0.00034257" ixy="0" ixz="0" iyy="0.0013205" iyz="0" izz="0.0010037"/>
      <!-- [kg m^2] [kg m^2] [kg m^2] [kg m^2] [kg m^2] [kg m^2] -->
    </inertial>
    <visual>
      <geometry>
        <mesh filename="package://reed_gazebo/meshes/reed_quad_x/rotortilt.STL" scale="1 1 1"/>
      </geometry>
    </visual>
    <collision>
      <geometry>
        <box size="0.005 0.005 0.005"/>
        <!-- [m] -->
      </geometry>
    </collision>
  </link>
  <gazebo>
    <plugin filename="librotors_gazebo_motor_model.so" name="six_tilt_unit_model">
      <robotNamespace>tilt_hex</robotNamespace>
      <jointName>tilt_hex/tilt_unit_5_revolutejoint</jointName>
      <linkName>tilt_hex/tilt_unit_5</linkName>
      <turningDirection>ccw</turningDirection>
      <motorType>position</motorType>
      <commandSubTopic>/gazebo/command/motor_speed</commandSubTopic>
      <motorNumber>17</motorNumber>
      <motorSpeedPubTopic>/tilt_motor_5/velocity</motorSpeedPubTopic>
      <motorPositionPubTopic>/tilt_motor_5/position</motorPositionPubTopic>
      <joint_control_pid>
        <p>1.0</p>
        <i>0.0</i>
        <d>0.01</d>
        <iMax>1.0</iMax>
        <iMin>-1.0</iMin>
        <cmdMax>2.0</cmdMax>
        <cmdMin>-2.0</cmdMin>
      </joint_control_pid>
    </plugin>
  </gazebo>
  <gazebo reference="tilt_hex/tilt_unit_5">
    <material>Gazebo/White</material>
  </gazebo>
  <!-- Rotor -->
  <joint name="rotor_5_joint" type="continuous">
    <origin rpy="0 0 0" xyz="0.22 0 0.04"/>
    <axis xyz="0 0 1"/>
    <parent link="tilt_hex/tilt_unit_5"/>
    <child link="rotor_5"/>
  </joint>
  <link name="rotor_5">
    <inertial>
      <mass value="0.005"/>
      <!-- [kg] -->
      <inertia ixx="9.7499961e-07" ixy="0.0" ixz="0.0" iyy="4.1704149985e-05" iyz="0.0" izz="4.2604149625e-05"/>
    </inertial>
    <visual>
      <geometry>
        <mesh filename="package://rotors_description/meshes/propeller_cw.dae" scale="0.1 0.1 0.1"/>
      </geometry>
    </visual>
    <collision>
      <geometry>
        <cylinder length="0.005" radius="0.1"/>
        <!-- [m] -->
      </geometry>
    </collision>
  </link>
  <gazebo>
    <plugin filename="librotors_gazebo_motor_model.so" name="six_motor_model">
      <robotNamespace>tilt_hex</robotNamespace>
      <jointName>rotor_5_joint</jointName>
      <linkName>rotor_5</linkName>
      <turningDirection>cw</turningDirection>
      <timeConstantUp>0.0125</timeConstantUp>
      <timeConstantDown>0.025</timeConstantDown>
      <maxRotVelocity>838</maxRotVelocity>
      <motorConstant>8.54858e-06</motorConstant>
      <momentConstant>0.016</momentConstant>
      <commandSubTopic>/gazebo/command/motor_speed</commandSubTopic>
      <motorNumber>5</motorNumber>
      <rotorDragCoefficient>8.06428e-05</rotorDragCoefficient>
      <rollingMomentCoefficient>1e-06</rollingMomentCoefficient>
      <motorSpeedPubTopic>/motor_speed/5</motorSpeedPubTopic>
      <rotorVelocitySlowdownSim>10</rotorVelocitySlowdownSim>
    </plugin>
  </gazebo>
  <gazebo reference="rotor_5">
    <material>Gazebo/Red</material>
  </gazebo>
</robot>

